Unhandled exception in thread started by <function check_errors.<locals>.wrapper at 0x7f515d652d90>
Traceback (most recent call last):
  File "/usr/local/lib/python3.4/dist-packages/django/apps/config.py", line 118, in create
    cls = getattr(mod, cls_name)
AttributeError: 'module' object has no attribute 'RcappConfig'

During handling of the above exception, another exception occurred:

Traceback (most recent call last):
  File "<frozen importlib._bootstrap>", line 2218, in _find_and_load_unlocked
AttributeError: 'module' object has no attribute '__path__'

During handling of the above exception, another exception occurred:

Traceback (most recent call last):
  File "/usr/local/lib/python3.4/dist-packages/django/utils/autoreload.py", line 226, in wrapper
    fn(*args, **kwargs)
  File "/usr/local/lib/python3.4/dist-packages/django/core/management/commands/runserver.py", line 113, in inner_run
    autoreload.raise_last_exception()
  File "/usr/local/lib/python3.4/dist-packages/django/utils/autoreload.py", line 249, in raise_last_exception
    six.reraise(*_exception)
  File "/usr/local/lib/python3.4/dist-packages/django/utils/six.py", line 685, in reraise
    raise value.with_traceback(tb)
  File "/usr/local/lib/python3.4/dist-packages/django/utils/autoreload.py", line 226, in wrapper
    fn(*args, **kwargs)
  File "/usr/local/lib/python3.4/dist-packages/django/__init__.py", line 27, in setup
    apps.populate(settings.INSTALLED_APPS)
  File "/usr/local/lib/python3.4/dist-packages/django/apps/registry.py", line 85, in populate
    app_config = AppConfig.create(entry)
  File "/usr/local/lib/python3.4/dist-packages/django/apps/config.py", line 123, in create
    import_module(entry)
  File "/usr/lib/python3.4/importlib/__init__.py", line 109, in import_module
    return _bootstrap._gcd_import(name[level:], package, level)
  File "<frozen importlib._bootstrap>", line 2254, in _gcd_import
  File "<frozen importlib._bootstrap>", line 2237, in _find_and_load
  File "<frozen importlib._bootstrap>", line 2221, in _find_and_load_unlocked
ImportError: No module named 'rcb.apps.RcappConfig'; 'rcb.apps' is not a package
Unhandled exception in thread started by <function check_errors.<locals>.wrapper at 0x7fd5dfaeed90>
Traceback (most recent call last):
  File "/usr/local/lib/python3.4/dist-packages/django/apps/config.py", line 118, in create
    cls = getattr(mod, cls_name)
AttributeError: 'module' object has no attribute 'RcappConfig'

During handling of the above exception, another exception occurred:

Traceback (most recent call last):
  File "<frozen importlib._bootstrap>", line 2218, in _find_and_load_unlocked
AttributeError: 'module' object has no attribute '__path__'

During handling of the above exception, another exception occurred:

Traceback (most recent call last):
  File "/usr/local/lib/python3.4/dist-packages/django/utils/autoreload.py", line 226, in wrapper
    fn(*args, **kwargs)
  File "/usr/local/lib/python3.4/dist-packages/django/core/management/commands/runserver.py", line 113, in inner_run
    autoreload.raise_last_exception()
  File "/usr/local/lib/python3.4/dist-packages/django/utils/autoreload.py", line 249, in raise_last_exception
    six.reraise(*_exception)
  File "/usr/local/lib/python3.4/dist-packages/django/utils/six.py", line 685, in reraise
    raise value.with_traceback(tb)
  File "/usr/local/lib/python3.4/dist-packages/django/utils/autoreload.py", line 226, in wrapper
    fn(*args, **kwargs)
  File "/usr/local/lib/python3.4/dist-packages/django/__init__.py", line 27, in setup
    apps.populate(settings.INSTALLED_APPS)
  File "/usr/local/lib/python3.4/dist-packages/django/apps/registry.py", line 85, in populate
    app_config = AppConfig.create(entry)
  File "/usr/local/lib/python3.4/dist-packages/django/apps/config.py", line 123, in create
    import_module(entry)
  File "/usr/lib/python3.4/importlib/__init__.py", line 109, in import_module
    return _bootstrap._gcd_import(name[level:], package, level)
  File "<frozen importlib._bootstrap>", line 2254, in _gcd_import
  File "<frozen importlib._bootstrap>", line 2237, in _find_and_load
  File "<frozen importlib._bootstrap>", line 2221, in _find_and_load_unlocked
ImportError: No module named 'rcb.apps.RcappConfig'; 'rcb.apps' is not a package
Unhandled exception in thread started by <function check_errors.<locals>.wrapper at 0x7f9f6e068d90>
Traceback (most recent call last):
  File "/usr/local/lib/python3.4/dist-packages/django/apps/config.py", line 118, in create
    cls = getattr(mod, cls_name)
AttributeError: 'module' object has no attribute 'RcappConfig'

During handling of the above exception, another exception occurred:

Traceback (most recent call last):
  File "<frozen importlib._bootstrap>", line 2218, in _find_and_load_unlocked
AttributeError: 'module' object has no attribute '__path__'

During handling of the above exception, another exception occurred:

Traceback (most recent call last):
  File "/usr/local/lib/python3.4/dist-packages/django/utils/autoreload.py", line 226, in wrapper
    fn(*args, **kwargs)
  File "/usr/local/lib/python3.4/dist-packages/django/core/management/commands/runserver.py", line 113, in inner_run
    autoreload.raise_last_exception()
  File "/usr/local/lib/python3.4/dist-packages/django/utils/autoreload.py", line 249, in raise_last_exception
    six.reraise(*_exception)
  File "/usr/local/lib/python3.4/dist-packages/django/utils/six.py", line 685, in reraise
    raise value.with_traceback(tb)
  File "/usr/local/lib/python3.4/dist-packages/django/utils/autoreload.py", line 226, in wrapper
    fn(*args, **kwargs)
  File "/usr/local/lib/python3.4/dist-packages/django/__init__.py", line 27, in setup
    apps.populate(settings.INSTALLED_APPS)
  File "/usr/local/lib/python3.4/dist-packages/django/apps/registry.py", line 85, in populate
    app_config = AppConfig.create(entry)
  File "/usr/local/lib/python3.4/dist-packages/django/apps/config.py", line 123, in create
    import_module(entry)
  File "/usr/lib/python3.4/importlib/__init__.py", line 109, in import_module
    return _bootstrap._gcd_import(name[level:], package, level)
  File "<frozen importlib._bootstrap>", line 2254, in _gcd_import
  File "<frozen importlib._bootstrap>", line 2237, in _find_and_load
  File "<frozen importlib._bootstrap>", line 2221, in _find_and_load_unlocked
ImportError: No module named 'rcb.apps.RcappConfig'; 'rcb.apps' is not a package
Unhandled exception in thread started by <function check_errors.<locals>.wrapper at 0x7fa29ca73ea0>
Traceback (most recent call last):
  File "/usr/local/lib/python3.4/dist-packages/django/utils/autoreload.py", line 226, in wrapper
    fn(*args, **kwargs)
  File "/usr/local/lib/python3.4/dist-packages/django/core/management/commands/runserver.py", line 121, in inner_run
    self.check(display_num_errors=True)
  File "/usr/local/lib/python3.4/dist-packages/django/core/management/base.py", line 385, in check
    include_deployment_checks=include_deployment_checks,
  File "/usr/local/lib/python3.4/dist-packages/django/core/management/base.py", line 372, in _run_checks
    return checks.run_checks(**kwargs)
  File "/usr/local/lib/python3.4/dist-packages/django/core/checks/registry.py", line 81, in run_checks
    new_errors = check(app_configs=app_configs)
  File "/usr/local/lib/python3.4/dist-packages/django/core/checks/urls.py", line 14, in check_url_config
    return check_resolver(resolver)
  File "/usr/local/lib/python3.4/dist-packages/django/core/checks/urls.py", line 24, in check_resolver
    for pattern in resolver.url_patterns:
  File "/usr/local/lib/python3.4/dist-packages/django/utils/functional.py", line 35, in __get__
    res = instance.__dict__[self.name] = self.func(instance)
  File "/usr/local/lib/python3.4/dist-packages/django/urls/resolvers.py", line 310, in url_patterns
    patterns = getattr(self.urlconf_module, "urlpatterns", self.urlconf_module)
  File "/usr/local/lib/python3.4/dist-packages/django/utils/functional.py", line 35, in __get__
    res = instance.__dict__[self.name] = self.func(instance)
  File "/usr/local/lib/python3.4/dist-packages/django/urls/resolvers.py", line 303, in urlconf_module
    return import_module(self.urlconf_name)
  File "/usr/lib/python3.4/importlib/__init__.py", line 109, in import_module
    return _bootstrap._gcd_import(name[level:], package, level)
  File "<frozen importlib._bootstrap>", line 2254, in _gcd_import
  File "<frozen importlib._bootstrap>", line 2237, in _find_and_load
  File "<frozen importlib._bootstrap>", line 2226, in _find_and_load_unlocked
  File "<frozen importlib._bootstrap>", line 1200, in _load_unlocked
  File "<frozen importlib._bootstrap>", line 1129, in _exec
  File "<frozen importlib._bootstrap>", line 1471, in exec_module
  File "<frozen importlib._bootstrap>", line 321, in _call_with_frames_removed
  File "/etc/side_projects/RCBuilder/RCBuilder/urls.py", line 23, in <module>
    url(r'^portal/', include('rcapp.urls')),
NameError: name 'include' is not defined
Performing system checks...

