[11/Dec/2016 19:57:53] "GET /admin/ HTTP/1.1" 200 13986
[11/Dec/2016 19:57:55] "GET /admin/auth/user/ HTTP/1.1" 200 6782
[11/Dec/2016 19:57:55] "GET /admin/jsi18n/ HTTP/1.1" 200 3189
Performing system checks...

System check identified no issues (0 silenced).
December 11, 2016 - 19:57:50
Django version 1.10, using settings 'RCBuilder.settings'
Starting development server at http://0.0.0.0:8080/
Quit the server with CONTROL-C.
Performing system checks...

System check identified no issues (0 silenced).
December 11, 2016 - 19:59:48
Django version 1.10, using settings 'RCBuilder.settings'
Starting development server at http://0.0.0.0:8080/
Quit the server with CONTROL-C.
[11/Dec/2016 20:00:00] "GET / HTTP/1.1" 200 12119
[11/Dec/2016 20:00:00] "GET /static/css/prettyPhoto.css HTTP/1.1" 200 19930
[11/Dec/2016 20:00:00] "GET /static/css/font-awesome.min.css HTTP/1.1" 200 20766
[11/Dec/2016 20:00:00] "GET /static/css/owl.carousel.css HTTP/1.1" 200 3149
[11/Dec/2016 20:00:00] "GET /static/css/responsive.css HTTP/1.1" 200 1013
[11/Dec/2016 20:00:00] "GET /static/css/main.css HTTP/1.1" 200 9043
[11/Dec/2016 20:00:00] "GET /static/js/vendor/modernizr-2.6.2.min.js HTTP/1.1" 200 15414
[11/Dec/2016 20:00:00] "GET /static/js/plugins.js HTTP/1.1" 200 733
[11/Dec/2016 20:00:00] "GET /static/js/wow.min.js HTTP/1.1" 200 7083
[11/Dec/2016 20:00:00] "GET /static/js/bootstrap.min.js HTTP/1.1" 200 31819
[11/Dec/2016 20:00:00] "GET /static/css/bootstrap.min.css HTTP/1.1" 200 116743
[11/Dec/2016 20:00:00] "GET /static/css/animate.css HTTP/1.1" 200 59839
[11/Dec/2016 20:00:00] "GET /static/js/prettyPhoto.js HTTP/1.1" 200 22060
[11/Dec/2016 20:00:00] "GET /static/js/owl.carousel.min.js HTTP/1.1" 200 23890
[11/Dec/2016 20:00:00] "GET /static/js/main.js HTTP/1.1" 200 1554
[11/Dec/2016 20:00:00] "GET /static/js/vendor/jquery-1.10.2.min.js HTTP/1.1" 200 93107
[11/Dec/2016 20:00:00] "GET /static/img/app-preview-empty.png HTTP/1.1" 200 43649
[11/Dec/2016 20:00:00] "GET /static/img/logo.png HTTP/1.1" 200 18815
[11/Dec/2016 20:00:01] "GET /static/img/header-bg.jpg HTTP/1.1" 200 2383551
[11/Dec/2016 20:00:02] "GET /static/img/header-bg.jpg HTTP/1.1" 200 2383551
[11/Dec/2016 20:00:05] "GET /portal/ HTTP/1.1" 200 10528
[11/Dec/2016 20:00:05] "GET /static/css/bootstrap.min.css HTTP/1.1" 304 0
[11/Dec/2016 20:00:05] "GET /static/css/font-awesome.min.css HTTP/1.1" 304 0
[11/Dec/2016 20:00:05] "GET /static/css/animate.css HTTP/1.1" 304 0
[11/Dec/2016 20:00:05] "GET /static/css/prettyPhoto.css HTTP/1.1" 304 0
[11/Dec/2016 20:00:05] "GET /static/css/owl.carousel.css HTTP/1.1" 304 0
[11/Dec/2016 20:00:05] "GET /static/css/main.css HTTP/1.1" 304 0
[11/Dec/2016 20:00:05] "GET /static/css/responsive.css HTTP/1.1" 304 0
[11/Dec/2016 20:00:05] "GET /static/js/vendor/jquery-1.10.2.min.js HTTP/1.1" 304 0
[11/Dec/2016 20:00:05] "GET /static/js/plugins.js HTTP/1.1" 304 0
[11/Dec/2016 20:00:05] "GET /static/js/wow.min.js HTTP/1.1" 304 0
[11/Dec/2016 20:00:05] "GET /static/js/bootstrap.min.js HTTP/1.1" 304 0
[11/Dec/2016 20:00:05] "GET /static/js/main.js HTTP/1.1" 304 0
[11/Dec/2016 20:00:05] "GET /static/js/owl.carousel.min.js HTTP/1.1" 304 0
[11/Dec/2016 20:00:05] "GET /static/js/prettyPhoto.js HTTP/1.1" 304 0
[11/Dec/2016 20:00:05] "GET /static/js/vendor/modernizr-2.6.2.min.js HTTP/1.1" 304 0
[11/Dec/2016 20:00:05] "GET /static/img/logo.png HTTP/1.1" 304 0
[11/Dec/2016 20:00:06] "GET /accounts/logout/ HTTP/1.1" 200 48
[11/Dec/2016 20:00:06] "GET / HTTP/1.1" 200 12083
[11/Dec/2016 20:00:06] "GET /static/img/header-bg.jpg HTTP/1.1" 304 0
[11/Dec/2016 20:00:06] "GET /static/img/app-preview-empty.png HTTP/1.1" 304 0
[11/Dec/2016 20:00:06] "GET /static/img/header-bg.jpg HTTP/1.1" 304 0
[11/Dec/2016 20:00:08] "GET /accounts/register/ HTTP/1.1" 200 1048
[11/Dec/2016 20:00:24] "POST /accounts/register/ HTTP/1.1" 200 1165
[11/Dec/2016 20:00:33] "GET /accounts/login/ HTTP/1.1" 200 1949
[11/Dec/2016 20:00:33] "GET /static/css/bootstrap.min.css HTTP/1.1" 304 0
[11/Dec/2016 20:00:33] "GET /static/js/ie-emulation-modes-warning.js HTTP/1.1" 200 2130
[11/Dec/2016 20:00:33] "GET /static/css/ie10-viewport-bug-workaround.css HTTP/1.1" 200 433
[11/Dec/2016 20:00:33] "GET /static/css/login.css HTTP/1.1" 200 1039
[11/Dec/2016 20:00:35] "POST /accounts/login/ HTTP/1.1" 200 1949
Performing system checks...

System check identified no issues (0 silenced).
December 11, 2016 - 19:59:53
Django version 1.10, using settings 'RCBuilder.settings'
Starting development server at http://0.0.0.0:8080/
Quit the server with CONTROL-C.
Performing system checks...

System check identified no issues (0 silenced).
December 11, 2016 - 20:01:33
Django version 1.10, using settings 'RCBuilder.settings'
Starting development server at http://0.0.0.0:8080/
Quit the server with CONTROL-C.
[11/Dec/2016 20:01:47] "GET /accounts/register/ HTTP/1.1" 200 2472
[11/Dec/2016 20:01:47] "GET /static/js/ie-emulation-modes-warning.js HTTP/1.1" 200 2130
[11/Dec/2016 20:01:47] "GET /static/css/login.css HTTP/1.1" 200 1039
[11/Dec/2016 20:01:47] "GET /static/css/ie10-viewport-bug-workaround.css HTTP/1.1" 200 433
[11/Dec/2016 20:01:47] "GET /static/css/bootstrap.min.css HTTP/1.1" 200 116743
[11/Dec/2016 20:02:05] "GET /accounts/register/ HTTP/1.1" 200 2472
[11/Dec/2016 20:02:05] "GET /static/css/bootstrap.min.css HTTP/1.1" 304 0
[11/Dec/2016 20:02:05] "GET /static/css/login.css HTTP/1.1" 304 0
[11/Dec/2016 20:02:05] "GET /static/js/ie-emulation-modes-warning.js HTTP/1.1" 304 0
[11/Dec/2016 20:02:05] "GET /static/css/ie10-viewport-bug-workaround.css HTTP/1.1" 304 0
[11/Dec/2016 20:28:05] "GET /accounts/register/ HTTP/1.1" 200 2472
[11/Dec/2016 20:28:05] "GET /static/css/ie10-viewport-bug-workaround.css HTTP/1.1" 304 0
[11/Dec/2016 20:28:05] "GET /static/js/ie-emulation-modes-warning.js HTTP/1.1" 304 0
[11/Dec/2016 20:28:05] "GET /static/css/bootstrap.min.css HTTP/1.1" 304 0
[11/Dec/2016 20:28:05] "GET /static/css/login.css HTTP/1.1" 304 0
[11/Dec/2016 20:28:08] "GET /accounts/register/ HTTP/1.1" 200 2472
[11/Dec/2016 20:28:13] "GET / HTTP/1.1" 200 12083
[11/Dec/2016 20:28:13] "GET /static/css/font-awesome.min.css HTTP/1.1" 200 20766
[11/Dec/2016 20:28:13] "GET /static/css/owl.carousel.css HTTP/1.1" 200 3149
[11/Dec/2016 20:28:13] "GET /static/css/prettyPhoto.css HTTP/1.1" 200 19930
[11/Dec/2016 20:28:13] "GET /static/css/main.css HTTP/1.1" 200 9043
[11/Dec/2016 20:28:13] "GET /static/css/responsive.css HTTP/1.1" 200 1013
[11/Dec/2016 20:28:13] "GET /static/css/animate.css HTTP/1.1" 200 59839
[11/Dec/2016 20:28:13] "GET /static/js/vendor/modernizr-2.6.2.min.js HTTP/1.1" 200 15414
[11/Dec/2016 20:28:13] "GET /static/js/plugins.js HTTP/1.1" 200 733
[11/Dec/2016 20:28:13] "GET /static/js/bootstrap.min.js HTTP/1.1" 200 31819
[11/Dec/2016 20:28:13] "GET /static/js/wow.min.js HTTP/1.1" 200 7083
[11/Dec/2016 20:28:13] "GET /static/js/prettyPhoto.js HTTP/1.1" 200 22060
[11/Dec/2016 20:28:13] "GET / HTTP/1.1" 200 12083
[11/Dec/2016 20:28:13] "GET /static/js/main.js HTTP/1.1" 200 1554
[11/Dec/2016 20:28:13] "GET /static/js/owl.carousel.min.js HTTP/1.1" 200 23890
[11/Dec/2016 20:28:13] "GET /static/js/vendor/jquery-1.10.2.min.js HTTP/1.1" 200 93107
[11/Dec/2016 20:28:14] "GET /static/img/logo.png HTTP/1.1" 200 18815
[11/Dec/2016 20:28:14] "GET /static/img/app-preview-empty.png HTTP/1.1" 200 43649
[11/Dec/2016 20:28:14] "GET /static/js/prettyPhoto.js HTTP/1.1" 200 22060
[11/Dec/2016 20:28:14] "GET /static/js/owl.carousel.min.js HTTP/1.1" 200 23890
[11/Dec/2016 20:28:14] "GET /static/js/vendor/jquery-1.10.2.min.js HTTP/1.1" 200 93107
[11/Dec/2016 20:28:15] "GET /static/img/header-bg.jpg HTTP/1.1" 200 2383551
[11/Dec/2016 20:28:15] "GET /static/img/header-bg.jpg HTTP/1.1" 200 2383551
[11/Dec/2016 20:28:23] "GET /accounts/login/ HTTP/1.1" 200 1949
[11/Dec/2016 20:28:25] "POST /accounts/login/ HTTP/1.1" 302 0
[11/Dec/2016 20:28:25] "GET /portal/ HTTP/1.1" 200 10528
Not Found: /portal/admin
[11/Dec/2016 20:28:36] "GET /portal/admin HTTP/1.1" 404 2862
[11/Dec/2016 20:28:38] "GET /portal/1 HTTP/1.1" 200 13297
[11/Dec/2016 20:28:39] "GET /portal/1 HTTP/1.1" 200 13297
Performing system checks...

System check identified no issues (0 silenced).
December 11, 2016 - 20:01:38
Django version 1.10, using settings 'RCBuilder.settings'
Starting development server at http://0.0.0.0:8080/
Quit the server with CONTROL-C.
Performing system checks...

System check identified no issues (0 silenced).
December 11, 2016 - 20:29:39
Django version 1.10, using settings 'RCBuilder.settings'
Starting development server at http://0.0.0.0:8080/
Quit the server with CONTROL-C.
[11/Dec/2016 20:29:48] "GET /portal/1 HTTP/1.1" 200 13297
[11/Dec/2016 20:29:51] "GET /portal/1 HTTP/1.1" 200 13297
[11/Dec/2016 20:29:51] "GET /static/css/prettyPhoto.css HTTP/1.1" 200 19930
[11/Dec/2016 20:29:51] "GET /static/css/owl.carousel.css HTTP/1.1" 200 3149
[11/Dec/2016 20:29:51] "GET /static/css/main.css HTTP/1.1" 200 9044
[11/Dec/2016 20:29:51] "GET /static/css/font-awesome.min.css HTTP/1.1" 200 20766
[11/Dec/2016 20:29:51] "GET /static/css/responsive.css HTTP/1.1" 200 1013
[11/Dec/2016 20:29:51] "GET /static/js/vendor/modernizr-2.6.2.min.js HTTP/1.1" 200 15414
[11/Dec/2016 20:29:51] "GET /static/js/plugins.js HTTP/1.1" 200 733
[11/Dec/2016 20:29:51] "GET /static/js/bootstrap.min.js HTTP/1.1" 200 31819
[11/Dec/2016 20:29:51] "GET /static/js/wow.min.js HTTP/1.1" 200 7083
[11/Dec/2016 20:29:51] "GET /static/css/animate.css HTTP/1.1" 200 59839
[11/Dec/2016 20:29:51] "GET /static/js/prettyPhoto.js HTTP/1.1" 200 22060
[11/Dec/2016 20:29:51] "GET /static/css/bootstrap.min.css HTTP/1.1" 200 116743
[11/Dec/2016 20:29:51] "GET /static/js/main.js HTTP/1.1" 200 1554
[11/Dec/2016 20:29:51] "GET /static/js/owl.carousel.min.js HTTP/1.1" 200 23890
[11/Dec/2016 20:29:51] "GET /static/js/vendor/jquery-1.10.2.min.js HTTP/1.1" 200 93107
[11/Dec/2016 20:29:51] "GET /static/img/logo.png HTTP/1.1" 200 18815
[11/Dec/2016 20:29:52] "GET /portal/1 HTTP/1.1" 200 13297
[11/Dec/2016 20:29:52] "GET /static/css/bootstrap.min.css HTTP/1.1" 304 0
[11/Dec/2016 20:29:52] "GET /static/css/font-awesome.min.css HTTP/1.1" 304 0
[11/Dec/2016 20:29:52] "GET /static/css/prettyPhoto.css HTTP/1.1" 304 0
[11/Dec/2016 20:29:52] "GET /static/css/animate.css HTTP/1.1" 304 0
[11/Dec/2016 20:29:52] "GET /static/css/responsive.css HTTP/1.1" 304 0
[11/Dec/2016 20:29:52] "GET /static/css/owl.carousel.css HTTP/1.1" 304 0
[11/Dec/2016 20:29:52] "GET /static/css/main.css HTTP/1.1" 304 0
[11/Dec/2016 20:29:52] "GET /static/js/vendor/jquery-1.10.2.min.js HTTP/1.1" 304 0
[11/Dec/2016 20:29:52] "GET /static/js/vendor/modernizr-2.6.2.min.js HTTP/1.1" 304 0
[11/Dec/2016 20:29:52] "GET /static/js/plugins.js HTTP/1.1" 304 0
[11/Dec/2016 20:29:52] "GET /static/js/prettyPhoto.js HTTP/1.1" 304 0
[11/Dec/2016 20:29:52] "GET /static/js/owl.carousel.min.js HTTP/1.1" 304 0
[11/Dec/2016 20:29:52] "GET /static/js/wow.min.js HTTP/1.1" 304 0
[11/Dec/2016 20:29:52] "GET /static/js/bootstrap.min.js HTTP/1.1" 304 0
[11/Dec/2016 20:29:52] "GET /static/js/main.js HTTP/1.1" 304 0
[11/Dec/2016 20:29:52] "GET /static/img/logo.png HTTP/1.1" 304 0
Not Found: /phpmyadmin
[11/Dec/2016 20:41:29] "HEAD /phpmyadmin HTTP/1.1" 404 2411
Performing system checks...

System check identified no issues (0 silenced).
December 11, 2016 - 20:29:44
Django version 1.10, using settings 'RCBuilder.settings'
Starting development server at http://0.0.0.0:8080/
Quit the server with CONTROL-C.
Performing system checks...

System check identified no issues (0 silenced).
December 11, 2016 - 20:49:34
Django version 1.10, using settings 'RCBuilder.settings'
Starting development server at http://0.0.0.0:8080/
Quit the server with CONTROL-C.
[11/Dec/2016 20:49:46] "GET /portal/ HTTP/1.1" 200 10528
[11/Dec/2016 20:49:46] "GET /static/css/font-awesome.min.css HTTP/1.1" 200 20766
[11/Dec/2016 20:49:46] "GET /static/css/prettyPhoto.css HTTP/1.1" 200 19930
[11/Dec/2016 20:49:46] "GET /static/css/owl.carousel.css HTTP/1.1" 200 3149
[11/Dec/2016 20:49:46] "GET /static/css/main.css HTTP/1.1" 200 9044
[11/Dec/2016 20:49:46] "GET /static/css/responsive.css HTTP/1.1" 200 1013
[11/Dec/2016 20:49:46] "GET /static/js/vendor/modernizr-2.6.2.min.js HTTP/1.1" 200 15414
[11/Dec/2016 20:49:46] "GET /static/css/animate.css HTTP/1.1" 200 59839
[11/Dec/2016 20:49:46] "GET /static/css/bootstrap.min.css HTTP/1.1" 200 116743
[11/Dec/2016 20:49:46] "GET /portal/ HTTP/1.1" 200 10528
[11/Dec/2016 20:49:46] "GET /static/js/bootstrap.min.js HTTP/1.1" 200 31819
[11/Dec/2016 20:49:46] "GET /static/js/plugins.js HTTP/1.1" 200 733
[11/Dec/2016 20:49:46] "GET /static/js/wow.min.js HTTP/1.1" 200 7083
[11/Dec/2016 20:49:46] "GET /static/js/prettyPhoto.js HTTP/1.1" 200 22060
[11/Dec/2016 20:49:46] "GET /static/js/owl.carousel.min.js HTTP/1.1" 200 23890
[11/Dec/2016 20:49:46] "GET /static/js/main.js HTTP/1.1" 200 1554
[11/Dec/2016 20:49:46] "GET /static/js/vendor/jquery-1.10.2.min.js HTTP/1.1" 200 93107
[11/Dec/2016 20:49:46] "GET /static/js/bootstrap.min.js HTTP/1.1" 200 31819
[11/Dec/2016 20:49:46] "GET /static/js/prettyPhoto.js HTTP/1.1" 200 22060
[11/Dec/2016 20:49:46] "GET /static/js/main.js HTTP/1.1" 200 1554
[11/Dec/2016 20:49:46] "GET /static/js/owl.carousel.min.js HTTP/1.1" 200 23890
[11/Dec/2016 20:49:47] "GET /static/img/logo.png HTTP/1.1" 200 18815
[11/Dec/2016 20:49:47] "GET /static/js/vendor/jquery-1.10.2.min.js HTTP/1.1" 200 93107
[11/Dec/2016 20:49:47] "GET /static/css/bootstrap.min.css HTTP/1.1" 200 116743
Internal Server Error: /portal/create/
Traceback (most recent call last):
  File "/usr/local/lib/python3.4/dist-packages/django/core/handlers/exception.py", line 39, in inner
    response = get_response(request)
  File "/usr/local/lib/python3.4/dist-packages/django/core/handlers/base.py", line 187, in _get_response
    response = self.process_exception_by_middleware(e, request)
  File "/usr/local/lib/python3.4/dist-packages/django/core/handlers/base.py", line 185, in _get_response
    response = wrapped_callback(request, *callback_args, **callback_kwargs)
  File "/usr/local/lib/python3.4/dist-packages/django/views/generic/base.py", line 68, in view
    return self.dispatch(request, *args, **kwargs)
  File "/usr/local/lib/python3.4/dist-packages/django/contrib/auth/mixins.py", line 56, in dispatch
    return super(LoginRequiredMixin, self).dispatch(request, *args, **kwargs)
  File "/usr/local/lib/python3.4/dist-packages/django/views/generic/base.py", line 88, in dispatch
    return handler(request, *args, **kwargs)
  File "/usr/local/lib/python3.4/dist-packages/django/views/generic/edit.py", line 213, in get
    return super(BaseCreateView, self).get(request, *args, **kwargs)
  File "/usr/local/lib/python3.4/dist-packages/django/views/generic/edit.py", line 174, in get
    return self.render_to_response(self.get_context_data())
  File "/usr/local/lib/python3.4/dist-packages/django/views/generic/edit.py", line 93, in get_context_data
    kwargs['form'] = self.get_form()
  File "/usr/local/lib/python3.4/dist-packages/django/views/generic/edit.py", line 44, in get_form
    form_class = self.get_form_class()
  File "/usr/local/lib/python3.4/dist-packages/django/views/generic/edit.py", line 129, in get_form_class
    "the 'fields' attribute is prohibited." % self.__class__.__name__
django.core.exceptions.ImproperlyConfigured: Using ModelFormMixin (base class of RCCreateView) without the 'fields' attribute is prohibited.
[11/Dec/2016 20:49:48] "GET /portal/create/ HTTP/1.1" 500 94628
Performing system checks...

System check identified no issues (0 silenced).
December 11, 2016 - 20:49:39
Django version 1.10, using settings 'RCBuilder.settings'
Starting development server at http://0.0.0.0:8080/
Quit the server with CONTROL-C.
Internal Server Error: /portal/create/
Traceback (most recent call last):
  File "/usr/local/lib/python3.4/dist-packages/django/core/handlers/exception.py", line 39, in inner
    response = get_response(request)
  File "/usr/local/lib/python3.4/dist-packages/django/core/handlers/base.py", line 187, in _get_response
    response = self.process_exception_by_middleware(e, request)
  File "/usr/local/lib/python3.4/dist-packages/django/core/handlers/base.py", line 185, in _get_response
    response = wrapped_callback(request, *callback_args, **callback_kwargs)
  File "/usr/local/lib/python3.4/dist-packages/django/views/generic/base.py", line 68, in view
    return self.dispatch(request, *args, **kwargs)
  File "/usr/local/lib/python3.4/dist-packages/django/contrib/auth/mixins.py", line 56, in dispatch
    return super(LoginRequiredMixin, self).dispatch(request, *args, **kwargs)
  File "/usr/local/lib/python3.4/dist-packages/django/views/generic/base.py", line 88, in dispatch
    return handler(request, *args, **kwargs)
  File "/usr/local/lib/python3.4/dist-packages/django/views/generic/edit.py", line 213, in get
    return super(BaseCreateView, self).get(request, *args, **kwargs)
  File "/usr/local/lib/python3.4/dist-packages/django/views/generic/edit.py", line 174, in get
    return self.render_to_response(self.get_context_data())
  File "/usr/local/lib/python3.4/dist-packages/django/views/generic/edit.py", line 93, in get_context_data
    kwargs['form'] = self.get_form()
  File "/usr/local/lib/python3.4/dist-packages/django/views/generic/edit.py", line 44, in get_form
    form_class = self.get_form_class()
  File "/usr/local/lib/python3.4/dist-packages/django/views/generic/edit.py", line 132, in get_form_class
    return model_forms.modelform_factory(model, fields=self.fields)
  File "/usr/local/lib/python3.4/dist-packages/django/forms/models.py", line 543, in modelform_factory
    return type(form)(class_name, (form,), form_class_attrs)
  File "/usr/local/lib/python3.4/dist-packages/django/forms/models.py", line 242, in __new__
    opts.field_classes)
  File "/usr/local/lib/python3.4/dist-packages/django/forms/models.py", line 138, in fields_for_model
    f.name, model.__name__)
django.core.exceptions.FieldError: 'formation_date' cannot be specified for ResultsChain model form as it is a non-editable field
[11/Dec/2016 20:52:16] "GET /portal/create/ HTTP/1.1" 500 114408
Performing system checks...

System check identified no issues (0 silenced).
December 11, 2016 - 20:52:13
Django version 1.10, using settings 'RCBuilder.settings'
Starting development server at http://0.0.0.0:8080/
Quit the server with CONTROL-C.
Performing system checks...

System check identified no issues (0 silenced).
December 11, 2016 - 20:52:18
Django version 1.10, using settings 'RCBuilder.settings'
Starting development server at http://0.0.0.0:8080/
Quit the server with CONTROL-C.
Performing system checks...

System check identified no issues (0 silenced).
December 11, 2016 - 20:52:37
Django version 1.10, using settings 'RCBuilder.settings'
Starting development server at http://0.0.0.0:8080/
Quit the server with CONTROL-C.
[11/Dec/2016 20:52:45] "GET /portal/create/ HTTP/1.1" 200 5570
[11/Dec/2016 20:52:45] "GET /static/css/owl.carousel.css HTTP/1.1" 200 3149
[11/Dec/2016 20:52:45] "GET /static/css/main.css HTTP/1.1" 200 9044
[11/Dec/2016 20:52:45] "GET /static/css/prettyPhoto.css HTTP/1.1" 200 19930
[11/Dec/2016 20:52:45] "GET /static/css/font-awesome.min.css HTTP/1.1" 200 20766
[11/Dec/2016 20:52:45] "GET /static/css/responsive.css HTTP/1.1" 200 1013
[11/Dec/2016 20:52:45] "GET /static/js/vendor/modernizr-2.6.2.min.js HTTP/1.1" 200 15414
[11/Dec/2016 20:52:45] "GET /static/css/animate.css HTTP/1.1" 200 59839
[11/Dec/2016 20:52:45] "GET /static/css/bootstrap.min.css HTTP/1.1" 200 116743
[11/Dec/2016 20:52:45] "GET /static/img/logo.png HTTP/1.1" 200 18815
Internal Server Error: /portal/create/
Traceback (most recent call last):
  File "/usr/local/lib/python3.4/dist-packages/django/db/backends/mysql/base.py", line 112, in execute
    return self.cursor.execute(query, args)
  File "/usr/local/lib/python3.4/dist-packages/MySQLdb/cursors.py", line 250, in execute
    self.errorhandler(self, exc, value)
  File "/usr/local/lib/python3.4/dist-packages/MySQLdb/connections.py", line 42, in defaulterrorhandler
    raise errorvalue
  File "/usr/local/lib/python3.4/dist-packages/MySQLdb/cursors.py", line 247, in execute
    res = self._query(query)
  File "/usr/local/lib/python3.4/dist-packages/MySQLdb/cursors.py", line 411, in _query
    rowcount = self._do_query(q)
  File "/usr/local/lib/python3.4/dist-packages/MySQLdb/cursors.py", line 374, in _do_query
    db.query(q)
  File "/usr/local/lib/python3.4/dist-packages/MySQLdb/connections.py", line 270, in query
    _mysql.connection.query(self, query)
_mysql_exceptions.OperationalError: (1048, "Column 'user_id' cannot be null")

During handling of the above exception, another exception occurred:

Traceback (most recent call last):
  File "/usr/local/lib/python3.4/dist-packages/django/core/handlers/exception.py", line 39, in inner
    response = get_response(request)
  File "/usr/local/lib/python3.4/dist-packages/django/core/handlers/base.py", line 187, in _get_response
    response = self.process_exception_by_middleware(e, request)
  File "/usr/local/lib/python3.4/dist-packages/django/core/handlers/base.py", line 185, in _get_response
    response = wrapped_callback(request, *callback_args, **callback_kwargs)
  File "/usr/local/lib/python3.4/dist-packages/django/views/generic/base.py", line 68, in view
    return self.dispatch(request, *args, **kwargs)
  File "/usr/local/lib/python3.4/dist-packages/django/contrib/auth/mixins.py", line 56, in dispatch
    return super(LoginRequiredMixin, self).dispatch(request, *args, **kwargs)
  File "/usr/local/lib/python3.4/dist-packages/django/views/generic/base.py", line 88, in dispatch
    return handler(request, *args, **kwargs)
  File "/usr/local/lib/python3.4/dist-packages/django/views/generic/edit.py", line 217, in post
    return super(BaseCreateView, self).post(request, *args, **kwargs)
  File "/usr/local/lib/python3.4/dist-packages/django/views/generic/edit.py", line 183, in post
    return self.form_valid(form)
  File "/usr/local/lib/python3.4/dist-packages/django/views/generic/edit.py", line 162, in form_valid
    self.object = form.save()
  File "/usr/local/lib/python3.4/dist-packages/django/forms/models.py", line 448, in save
    self.instance.save()
  File "/usr/local/lib/python3.4/dist-packages/django/db/models/base.py", line 796, in save
    force_update=force_update, update_fields=update_fields)
  File "/usr/local/lib/python3.4/dist-packages/django/db/models/base.py", line 824, in save_base
    updated = self._save_table(raw, cls, force_insert, force_update, using, update_fields)
  File "/usr/local/lib/python3.4/dist-packages/django/db/models/base.py", line 908, in _save_table
    result = self._do_insert(cls._base_manager, using, fields, update_pk, raw)
  File "/usr/local/lib/python3.4/dist-packages/django/db/models/base.py", line 947, in _do_insert
    using=using, raw=raw)
  File "/usr/local/lib/python3.4/dist-packages/django/db/models/manager.py", line 85, in manager_method
    return getattr(self.get_queryset(), name)(*args, **kwargs)
  File "/usr/local/lib/python3.4/dist-packages/django/db/models/query.py", line 1043, in _insert
    return query.get_compiler(using=using).execute_sql(return_id)
  File "/usr/local/lib/python3.4/dist-packages/django/db/models/sql/compiler.py", line 1054, in execute_sql
    cursor.execute(sql, params)
  File "/usr/local/lib/python3.4/dist-packages/django/db/backends/utils.py", line 79, in execute
    return super(CursorDebugWrapper, self).execute(sql, params)
  File "/usr/local/lib/python3.4/dist-packages/django/db/backends/utils.py", line 64, in execute
    return self.cursor.execute(sql, params)
  File "/usr/local/lib/python3.4/dist-packages/django/db/backends/mysql/base.py", line 117, in execute
    six.reraise(utils.IntegrityError, utils.IntegrityError(*tuple(e.args)), sys.exc_info()[2])
  File "/usr/local/lib/python3.4/dist-packages/django/utils/six.py", line 685, in reraise
    raise value.with_traceback(tb)
  File "/usr/local/lib/python3.4/dist-packages/django/db/backends/mysql/base.py", line 112, in execute
    return self.cursor.execute(query, args)
  File "/usr/local/lib/python3.4/dist-packages/MySQLdb/cursors.py", line 250, in execute
    self.errorhandler(self, exc, value)
  File "/usr/local/lib/python3.4/dist-packages/MySQLdb/connections.py", line 42, in defaulterrorhandler
    raise errorvalue
  File "/usr/local/lib/python3.4/dist-packages/MySQLdb/cursors.py", line 247, in execute
    res = self._query(query)
  File "/usr/local/lib/python3.4/dist-packages/MySQLdb/cursors.py", line 411, in _query
    rowcount = self._do_query(q)
  File "/usr/local/lib/python3.4/dist-packages/MySQLdb/cursors.py", line 374, in _do_query
    db.query(q)
  File "/usr/local/lib/python3.4/dist-packages/MySQLdb/connections.py", line 270, in query
    _mysql.connection.query(self, query)
django.db.utils.IntegrityError: (1048, "Column 'user_id' cannot be null")
[11/Dec/2016 20:53:05] "POST /portal/create/ HTTP/1.1" 500 207312
Performing system checks...

System check identified no issues (0 silenced).
December 11, 2016 - 20:52:42
Django version 1.10, using settings 'RCBuilder.settings'
Starting development server at http://0.0.0.0:8080/
Quit the server with CONTROL-C.
Unhandled exception in thread started by <function check_errors.<locals>.wrapper at 0x7f8964112950>
Traceback (most recent call last):
  File "/usr/local/lib/python3.4/dist-packages/django/utils/autoreload.py", line 226, in wrapper
    fn(*args, **kwargs)
  File "/usr/local/lib/python3.4/dist-packages/django/core/management/commands/runserver.py", line 121, in inner_run
    self.check(display_num_errors=True)
  File "/usr/local/lib/python3.4/dist-packages/django/core/management/base.py", line 385, in check
    include_deployment_checks=include_deployment_checks,
  File "/usr/local/lib/python3.4/dist-packages/django/core/management/base.py", line 372, in _run_checks
    return checks.run_checks(**kwargs)
  File "/usr/local/lib/python3.4/dist-packages/django/core/checks/registry.py", line 81, in run_checks
    new_errors = check(app_configs=app_configs)
  File "/usr/local/lib/python3.4/dist-packages/django/core/checks/urls.py", line 14, in check_url_config
    return check_resolver(resolver)
  File "/usr/local/lib/python3.4/dist-packages/django/core/checks/urls.py", line 24, in check_resolver
    for pattern in resolver.url_patterns:
  File "/usr/local/lib/python3.4/dist-packages/django/utils/functional.py", line 35, in __get__
    res = instance.__dict__[self.name] = self.func(instance)
  File "/usr/local/lib/python3.4/dist-packages/django/urls/resolvers.py", line 310, in url_patterns
    patterns = getattr(self.urlconf_module, "urlpatterns", self.urlconf_module)
  File "/usr/local/lib/python3.4/dist-packages/django/utils/functional.py", line 35, in __get__
    res = instance.__dict__[self.name] = self.func(instance)
  File "/usr/local/lib/python3.4/dist-packages/django/urls/resolvers.py", line 303, in urlconf_module
    return import_module(self.urlconf_name)
  File "/usr/lib/python3.4/importlib/__init__.py", line 109, in import_module
    return _bootstrap._gcd_import(name[level:], package, level)
  File "<frozen importlib._bootstrap>", line 2254, in _gcd_import
  File "<frozen importlib._bootstrap>", line 2237, in _find_and_load
  File "<frozen importlib._bootstrap>", line 2226, in _find_and_load_unlocked
  File "<frozen importlib._bootstrap>", line 1200, in _load_unlocked
  File "<frozen importlib._bootstrap>", line 1129, in _exec
  File "<frozen importlib._bootstrap>", line 1471, in exec_module
  File "<frozen importlib._bootstrap>", line 321, in _call_with_frames_removed
  File "/etc/side_projects/RCBuilder/RCBuilder/urls.py", line 25, in <module>
    url(r'^portal/', include('rcapp.urls')),
  File "/usr/local/lib/python3.4/dist-packages/django/conf/urls/__init__.py", line 50, in include
    urlconf_module = import_module(urlconf_module)
  File "/usr/lib/python3.4/importlib/__init__.py", line 109, in import_module
    return _bootstrap._gcd_import(name[level:], package, level)
  File "<frozen importlib._bootstrap>", line 2254, in _gcd_import
  File "<frozen importlib._bootstrap>", line 2237, in _find_and_load
  File "<frozen importlib._bootstrap>", line 2226, in _find_and_load_unlocked
  File "<frozen importlib._bootstrap>", line 1200, in _load_unlocked
  File "<frozen importlib._bootstrap>", line 1129, in _exec
  File "<frozen importlib._bootstrap>", line 1471, in exec_module
  File "<frozen importlib._bootstrap>", line 321, in _call_with_frames_removed
  File "/etc/side_projects/RCBuilder/rcapp/urls.py", line 3, in <module>
    from . import views
  File "/etc/side_projects/RCBuilder/rcapp/views.py", line 55
    return redirect(self.object.get_absolute_url())
    ^
IndentationError: unexpected indent
Performing system checks...

Unhandled exception in thread started by <function check_errors.<locals>.wrapper at 0x7fb36323ab70>
Traceback (most recent call last):
  File "/usr/local/lib/python3.4/dist-packages/django/utils/autoreload.py", line 226, in wrapper
    fn(*args, **kwargs)
  File "/usr/local/lib/python3.4/dist-packages/django/core/management/commands/runserver.py", line 121, in inner_run
    self.check(display_num_errors=True)
  File "/usr/local/lib/python3.4/dist-packages/django/core/management/base.py", line 385, in check
    include_deployment_checks=include_deployment_checks,
  File "/usr/local/lib/python3.4/dist-packages/django/core/management/base.py", line 372, in _run_checks
    return checks.run_checks(**kwargs)
  File "/usr/local/lib/python3.4/dist-packages/django/core/checks/registry.py", line 81, in run_checks
    new_errors = check(app_configs=app_configs)
  File "/usr/local/lib/python3.4/dist-packages/django/core/checks/urls.py", line 14, in check_url_config
    return check_resolver(resolver)
  File "/usr/local/lib/python3.4/dist-packages/django/core/checks/urls.py", line 24, in check_resolver
    for pattern in resolver.url_patterns:
  File "/usr/local/lib/python3.4/dist-packages/django/utils/functional.py", line 35, in __get__
    res = instance.__dict__[self.name] = self.func(instance)
  File "/usr/local/lib/python3.4/dist-packages/django/urls/resolvers.py", line 310, in url_patterns
    patterns = getattr(self.urlconf_module, "urlpatterns", self.urlconf_module)
  File "/usr/local/lib/python3.4/dist-packages/django/utils/functional.py", line 35, in __get__
    res = instance.__dict__[self.name] = self.func(instance)
  File "/usr/local/lib/python3.4/dist-packages/django/urls/resolvers.py", line 303, in urlconf_module
    return import_module(self.urlconf_name)
  File "/usr/lib/python3.4/importlib/__init__.py", line 109, in import_module
    return _bootstrap._gcd_import(name[level:], package, level)
  File "<frozen importlib._bootstrap>", line 2254, in _gcd_import
  File "<frozen importlib._bootstrap>", line 2237, in _find_and_load
  File "<frozen importlib._bootstrap>", line 2226, in _find_and_load_unlocked
  File "<frozen importlib._bootstrap>", line 1200, in _load_unlocked
  File "<frozen importlib._bootstrap>", line 1129, in _exec
  File "<frozen importlib._bootstrap>", line 1471, in exec_module
  File "<frozen importlib._bootstrap>", line 321, in _call_with_frames_removed
  File "/etc/side_projects/RCBuilder/RCBuilder/urls.py", line 25, in <module>
    url(r'^portal/', include('rcapp.urls')),
  File "/usr/local/lib/python3.4/dist-packages/django/conf/urls/__init__.py", line 50, in include
    urlconf_module = import_module(urlconf_module)
  File "/usr/lib/python3.4/importlib/__init__.py", line 109, in import_module
    return _bootstrap._gcd_import(name[level:], package, level)
  File "<frozen importlib._bootstrap>", line 2254, in _gcd_import
  File "<frozen importlib._bootstrap>", line 2237, in _find_and_load
  File "<frozen importlib._bootstrap>", line 2226, in _find_and_load_unlocked
  File "<frozen importlib._bootstrap>", line 1200, in _load_unlocked
  File "<frozen importlib._bootstrap>", line 1129, in _exec
  File "<frozen importlib._bootstrap>", line 1471, in exec_module
  File "<frozen importlib._bootstrap>", line 321, in _call_with_frames_removed
  File "/etc/side_projects/RCBuilder/rcapp/urls.py", line 3, in <module>
    from . import views
  File "/etc/side_projects/RCBuilder/rcapp/views.py", line 55
    return redirect(self.object.get_absolute_url())
    ^
IndentationError: unexpected indent
Performing system checks...

Unhandled exception in thread started by <function check_errors.<locals>.wrapper at 0x7f6fa0f79950>
Traceback (most recent call last):
  File "/usr/local/lib/python3.4/dist-packages/django/utils/autoreload.py", line 226, in wrapper
    fn(*args, **kwargs)
  File "/usr/local/lib/python3.4/dist-packages/django/core/management/commands/runserver.py", line 121, in inner_run
    self.check(display_num_errors=True)
  File "/usr/local/lib/python3.4/dist-packages/django/core/management/base.py", line 385, in check
    include_deployment_checks=include_deployment_checks,
  File "/usr/local/lib/python3.4/dist-packages/django/core/management/base.py", line 372, in _run_checks
    return checks.run_checks(**kwargs)
  File "/usr/local/lib/python3.4/dist-packages/django/core/checks/registry.py", line 81, in run_checks
    new_errors = check(app_configs=app_configs)
  File "/usr/local/lib/python3.4/dist-packages/django/core/checks/urls.py", line 14, in check_url_config
    return check_resolver(resolver)
  File "/usr/local/lib/python3.4/dist-packages/django/core/checks/urls.py", line 24, in check_resolver
    for pattern in resolver.url_patterns:
  File "/usr/local/lib/python3.4/dist-packages/django/utils/functional.py", line 35, in __get__
    res = instance.__dict__[self.name] = self.func(instance)
  File "/usr/local/lib/python3.4/dist-packages/django/urls/resolvers.py", line 310, in url_patterns
    patterns = getattr(self.urlconf_module, "urlpatterns", self.urlconf_module)
  File "/usr/local/lib/python3.4/dist-packages/django/utils/functional.py", line 35, in __get__
    res = instance.__dict__[self.name] = self.func(instance)
  File "/usr/local/lib/python3.4/dist-packages/django/urls/resolvers.py", line 303, in urlconf_module
    return import_module(self.urlconf_name)
  File "/usr/lib/python3.4/importlib/__init__.py", line 109, in import_module
    return _bootstrap._gcd_import(name[level:], package, level)
  File "<frozen importlib._bootstrap>", line 2254, in _gcd_import
  File "<frozen importlib._bootstrap>", line 2237, in _find_and_load
  File "<frozen importlib._bootstrap>", line 2226, in _find_and_load_unlocked
  File "<frozen importlib._bootstrap>", line 1200, in _load_unlocked
  File "<frozen importlib._bootstrap>", line 1129, in _exec
  File "<frozen importlib._bootstrap>", line 1471, in exec_module
  File "<frozen importlib._bootstrap>", line 321, in _call_with_frames_removed
  File "/etc/side_projects/RCBuilder/RCBuilder/urls.py", line 25, in <module>
    url(r'^portal/', include('rcapp.urls')),
  File "/usr/local/lib/python3.4/dist-packages/django/conf/urls/__init__.py", line 50, in include
    urlconf_module = import_module(urlconf_module)
  File "/usr/lib/python3.4/importlib/__init__.py", line 109, in import_module
    return _bootstrap._gcd_import(name[level:], package, level)
  File "<frozen importlib._bootstrap>", line 2254, in _gcd_import
  File "<frozen importlib._bootstrap>", line 2237, in _find_and_load
  File "<frozen importlib._bootstrap>", line 2226, in _find_and_load_unlocked
  File "<frozen importlib._bootstrap>", line 1200, in _load_unlocked
  File "<frozen importlib._bootstrap>", line 1129, in _exec
  File "<frozen importlib._bootstrap>", line 1471, in exec_module
  File "<frozen importlib._bootstrap>", line 321, in _call_with_frames_removed
  File "/etc/side_projects/RCBuilder/rcapp/urls.py", line 3, in <module>
    from . import views
  File "/etc/side_projects/RCBuilder/rcapp/views.py", line 55
    return redirect(self.object.get_absolute_url())
    ^
IndentationError: unexpected indent
Performing system checks...

Unhandled exception in thread started by <function check_errors.<locals>.wrapper at 0x7f9ad8cd9b70>
Traceback (most recent call last):
  File "/usr/local/lib/python3.4/dist-packages/django/utils/autoreload.py", line 226, in wrapper
    fn(*args, **kwargs)
  File "/usr/local/lib/python3.4/dist-packages/django/core/management/commands/runserver.py", line 121, in inner_run
    self.check(display_num_errors=True)
  File "/usr/local/lib/python3.4/dist-packages/django/core/management/base.py", line 385, in check
    include_deployment_checks=include_deployment_checks,
  File "/usr/local/lib/python3.4/dist-packages/django/core/management/base.py", line 372, in _run_checks
    return checks.run_checks(**kwargs)
  File "/usr/local/lib/python3.4/dist-packages/django/core/checks/registry.py", line 81, in run_checks
    new_errors = check(app_configs=app_configs)
  File "/usr/local/lib/python3.4/dist-packages/django/core/checks/urls.py", line 14, in check_url_config
    return check_resolver(resolver)
  File "/usr/local/lib/python3.4/dist-packages/django/core/checks/urls.py", line 24, in check_resolver
    for pattern in resolver.url_patterns:
  File "/usr/local/lib/python3.4/dist-packages/django/utils/functional.py", line 35, in __get__
    res = instance.__dict__[self.name] = self.func(instance)
  File "/usr/local/lib/python3.4/dist-packages/django/urls/resolvers.py", line 310, in url_patterns
    patterns = getattr(self.urlconf_module, "urlpatterns", self.urlconf_module)
  File "/usr/local/lib/python3.4/dist-packages/django/utils/functional.py", line 35, in __get__
    res = instance.__dict__[self.name] = self.func(instance)
  File "/usr/local/lib/python3.4/dist-packages/django/urls/resolvers.py", line 303, in urlconf_module
    return import_module(self.urlconf_name)
  File "/usr/lib/python3.4/importlib/__init__.py", line 109, in import_module
    return _bootstrap._gcd_import(name[level:], package, level)
  File "<frozen importlib._bootstrap>", line 2254, in _gcd_import
  File "<frozen importlib._bootstrap>", line 2237, in _find_and_load
  File "<frozen importlib._bootstrap>", line 2226, in _find_and_load_unlocked
  File "<frozen importlib._bootstrap>", line 1200, in _load_unlocked
  File "<frozen importlib._bootstrap>", line 1129, in _exec
  File "<frozen importlib._bootstrap>", line 1471, in exec_module
  File "<frozen importlib._bootstrap>", line 321, in _call_with_frames_removed
  File "/etc/side_projects/RCBuilder/RCBuilder/urls.py", line 25, in <module>
    url(r'^portal/', include('rcapp.urls')),
  File "/usr/local/lib/python3.4/dist-packages/django/conf/urls/__init__.py", line 50, in include
    urlconf_module = import_module(urlconf_module)
  File "/usr/lib/python3.4/importlib/__init__.py", line 109, in import_module
    return _bootstrap._gcd_import(name[level:], package, level)
  File "<frozen importlib._bootstrap>", line 2254, in _gcd_import
  File "<frozen importlib._bootstrap>", line 2237, in _find_and_load
  File "<frozen importlib._bootstrap>", line 2226, in _find_and_load_unlocked
  File "<frozen importlib._bootstrap>", line 1200, in _load_unlocked
  File "<frozen importlib._bootstrap>", line 1129, in _exec
  File "<frozen importlib._bootstrap>", line 1471, in exec_module
  File "<frozen importlib._bootstrap>", line 321, in _call_with_frames_removed
  File "/etc/side_projects/RCBuilder/rcapp/urls.py", line 3, in <module>
    from . import views
  File "/etc/side_projects/RCBuilder/rcapp/views.py", line 55
    return redirect(self.object.get_absolute_url())
    ^
IndentationError: unexpected indent
Performing system checks...

[11/Dec/2016 20:58:05] "GET /portal/create/ HTTP/1.1" 200 5570
[11/Dec/2016 20:58:05] "GET /static/css/owl.carousel.css HTTP/1.1" 200 3149
[11/Dec/2016 20:58:05] "GET /static/css/main.css HTTP/1.1" 200 9044
[11/Dec/2016 20:58:05] "GET /static/css/font-awesome.min.css HTTP/1.1" 200 20766
[11/Dec/2016 20:58:05] "GET /static/css/prettyPhoto.css HTTP/1.1" 200 19930
[11/Dec/2016 20:58:05] "GET /static/css/animate.css HTTP/1.1" 200 59839
[11/Dec/2016 20:58:05] "GET /static/css/responsive.css HTTP/1.1" 200 1013
[11/Dec/2016 20:58:05] "GET /static/js/vendor/modernizr-2.6.2.min.js HTTP/1.1" 200 15414
[11/Dec/2016 20:58:06] "GET /static/css/bootstrap.min.css HTTP/1.1" 200 116743
[11/Dec/2016 20:58:06] "GET /static/img/logo.png HTTP/1.1" 200 18815
Performing system checks...

System check identified no issues (0 silenced).
December 11, 2016 - 20:58:04
Django version 1.10, using settings 'RCBuilder.settings'
Starting development server at http://0.0.0.0:8080/
Quit the server with CONTROL-C.
Internal Server Error: /portal/create/
Traceback (most recent call last):
  File "/usr/local/lib/python3.4/dist-packages/django/core/handlers/exception.py", line 39, in inner
    response = get_response(request)
  File "/usr/local/lib/python3.4/dist-packages/django/core/handlers/base.py", line 187, in _get_response
    response = self.process_exception_by_middleware(e, request)
  File "/usr/local/lib/python3.4/dist-packages/django/core/handlers/base.py", line 185, in _get_response
    response = wrapped_callback(request, *callback_args, **callback_kwargs)
  File "/usr/local/lib/python3.4/dist-packages/django/views/generic/base.py", line 68, in view
    return self.dispatch(request, *args, **kwargs)
  File "/usr/local/lib/python3.4/dist-packages/django/contrib/auth/mixins.py", line 56, in dispatch
    return super(LoginRequiredMixin, self).dispatch(request, *args, **kwargs)
  File "/usr/local/lib/python3.4/dist-packages/django/views/generic/base.py", line 88, in dispatch
    return handler(request, *args, **kwargs)
  File "/usr/local/lib/python3.4/dist-packages/django/views/generic/edit.py", line 217, in post
    return super(BaseCreateView, self).post(request, *args, **kwargs)
  File "/usr/local/lib/python3.4/dist-packages/django/views/generic/edit.py", line 183, in post
    return self.form_valid(form)
  File "/etc/side_projects/RCBuilder/rcapp/views.py", line 53, in form_valid
    self.object.user = self.request.user
AttributeError: 'NoneType' object has no attribute 'user'
[11/Dec/2016 20:58:19] "POST /portal/create/ HTTP/1.1" 500 87530
Performing system checks...

System check identified no issues (0 silenced).
December 11, 2016 - 20:58:09
Django version 1.10, using settings 'RCBuilder.settings'
Starting development server at http://0.0.0.0:8080/
Quit the server with CONTROL-C.
[11/Dec/2016 21:01:11] "GET /portal/create/ HTTP/1.1" 200 5570
[11/Dec/2016 21:01:11] "GET /static/css/owl.carousel.css HTTP/1.1" 200 3149
[11/Dec/2016 21:01:11] "GET /static/css/prettyPhoto.css HTTP/1.1" 200 19930
[11/Dec/2016 21:01:11] "GET /static/img/logo.png HTTP/1.1" 200 18815
[11/Dec/2016 21:01:11] "GET /static/css/font-awesome.min.css HTTP/1.1" 200 20766
[11/Dec/2016 21:01:11] "GET /static/js/vendor/modernizr-2.6.2.min.js HTTP/1.1" 200 15414
[11/Dec/2016 21:01:11] "GET /static/css/responsive.css HTTP/1.1" 200 1013
[11/Dec/2016 21:01:11] "GET /static/css/animate.css HTTP/1.1" 200 59839
[11/Dec/2016 21:01:11] "GET /static/css/owl.carousel.css HTTP/1.1" 200 3149
[11/Dec/2016 21:01:11] "GET /static/css/font-awesome.min.css HTTP/1.1" 200 20766
[11/Dec/2016 21:01:11] "GET /static/css/prettyPhoto.css HTTP/1.1" 200 19930
[11/Dec/2016 21:01:11] "GET /static/css/bootstrap.min.css HTTP/1.1" 200 116743
[11/Dec/2016 21:01:11] "GET /static/css/responsive.css HTTP/1.1" 200 1013
[11/Dec/2016 21:01:11] "GET /static/css/main.css HTTP/1.1" 200 9044
[11/Dec/2016 21:01:11] "GET /static/js/vendor/modernizr-2.6.2.min.js HTTP/1.1" 200 15414
[11/Dec/2016 21:01:11] "GET /static/css/main.css HTTP/1.1" 200 9044
[11/Dec/2016 21:01:11] "GET /static/css/animate.css HTTP/1.1" 200 59839
[11/Dec/2016 21:01:12] "GET /static/css/bootstrap.min.css HTTP/1.1" 200 116743
[11/Dec/2016 21:01:12] "GET /static/img/logo.png HTTP/1.1" 200 18815
Performing system checks...

System check identified no issues (0 silenced).
December 11, 2016 - 21:01:07
Django version 1.10, using settings 'RCBuilder.settings'
Starting development server at http://0.0.0.0:8080/
Quit the server with CONTROL-C.
Internal Server Error: /portal/create/
Traceback (most recent call last):
  File "/usr/local/lib/python3.4/dist-packages/django/core/handlers/exception.py", line 39, in inner
    response = get_response(request)
  File "/usr/local/lib/python3.4/dist-packages/django/core/handlers/base.py", line 187, in _get_response
    response = self.process_exception_by_middleware(e, request)
  File "/usr/local/lib/python3.4/dist-packages/django/core/handlers/base.py", line 185, in _get_response
    response = wrapped_callback(request, *callback_args, **callback_kwargs)
  File "/usr/local/lib/python3.4/dist-packages/django/views/generic/base.py", line 68, in view
    return self.dispatch(request, *args, **kwargs)
  File "/usr/local/lib/python3.4/dist-packages/django/contrib/auth/mixins.py", line 56, in dispatch
    return super(LoginRequiredMixin, self).dispatch(request, *args, **kwargs)
  File "/usr/local/lib/python3.4/dist-packages/django/views/generic/base.py", line 88, in dispatch
    return handler(request, *args, **kwargs)
  File "/usr/local/lib/python3.4/dist-packages/django/views/generic/edit.py", line 217, in post
    return super(BaseCreateView, self).post(request, *args, **kwargs)
  File "/usr/local/lib/python3.4/dist-packages/django/views/generic/edit.py", line 183, in post
    return self.form_valid(form)
  File "/etc/side_projects/RCBuilder/rcapp/views.py", line 56, in form_valid
    return redirect(self.object.get_absolute_url())
AttributeError: 'ResultsChain' object has no attribute 'get_absolute_url'
[11/Dec/2016 21:01:25] "POST /portal/create/ HTTP/1.1" 500 87153
[11/Dec/2016 21:01:33] "GET /admin/rcb/description/ HTTP/1.1" 200 3097
[11/Dec/2016 21:01:33] "GET /admin/jsi18n/ HTTP/1.1" 200 3189
[11/Dec/2016 21:01:34] "GET /admin/rcb/description/ HTTP/1.1" 200 3097
[11/Dec/2016 21:01:34] "GET /admin/jsi18n/ HTTP/1.1" 200 3189
[11/Dec/2016 21:01:36] "GET /admin/rcb/ HTTP/1.1" 200 3136
[11/Dec/2016 21:01:38] "GET /admin/ HTTP/1.1" 200 13986
[11/Dec/2016 21:01:44] "GET /admin/rcapp/resultschain/ HTTP/1.1" 200 4934
[11/Dec/2016 21:01:44] "GET /admin/jsi18n/ HTTP/1.1" 200 3189
[11/Dec/2016 21:01:46] "GET /admin/rcapp/resultschain/3/change/ HTTP/1.1" 200 6936
[11/Dec/2016 21:01:46] "GET /admin/jsi18n/ HTTP/1.1" 200 3189
[11/Dec/2016 21:01:46] "GET /static/admin/js/change_form.js HTTP/1.1" 200 698
Performing system checks...

System check identified no issues (0 silenced).
December 11, 2016 - 21:01:12
Django version 1.10, using settings 'RCBuilder.settings'
Starting development server at http://0.0.0.0:8080/
Quit the server with CONTROL-C.
Unhandled exception in thread started by <function check_errors.<locals>.wrapper at 0x7fa49051f620>
Traceback (most recent call last):
  File "/usr/local/lib/python3.4/dist-packages/django/utils/autoreload.py", line 226, in wrapper
    fn(*args, **kwargs)
  File "/usr/local/lib/python3.4/dist-packages/django/core/management/commands/runserver.py", line 113, in inner_run
    autoreload.raise_last_exception()
  File "/usr/local/lib/python3.4/dist-packages/django/utils/autoreload.py", line 249, in raise_last_exception
    six.reraise(*_exception)
  File "/usr/local/lib/python3.4/dist-packages/django/utils/six.py", line 685, in reraise
    raise value.with_traceback(tb)
  File "/usr/local/lib/python3.4/dist-packages/django/utils/autoreload.py", line 226, in wrapper
    fn(*args, **kwargs)
  File "/usr/local/lib/python3.4/dist-packages/django/__init__.py", line 27, in setup
    apps.populate(settings.INSTALLED_APPS)
  File "/usr/local/lib/python3.4/dist-packages/django/apps/registry.py", line 108, in populate
    app_config.import_models(all_models)
  File "/usr/local/lib/python3.4/dist-packages/django/apps/config.py", line 199, in import_models
    self.models_module = import_module(models_module_name)
  File "/usr/lib/python3.4/importlib/__init__.py", line 109, in import_module
    return _bootstrap._gcd_import(name[level:], package, level)
  File "<frozen importlib._bootstrap>", line 2254, in _gcd_import
  File "<frozen importlib._bootstrap>", line 2237, in _find_and_load
  File "<frozen importlib._bootstrap>", line 2226, in _find_and_load_unlocked
  File "<frozen importlib._bootstrap>", line 1200, in _load_unlocked
  File "<frozen importlib._bootstrap>", line 1129, in _exec
  File "<frozen importlib._bootstrap>", line 1467, in exec_module
  File "<frozen importlib._bootstrap>", line 1572, in get_code
  File "<frozen importlib._bootstrap>", line 1532, in source_to_code
  File "<frozen importlib._bootstrap>", line 321, in _call_with_frames_removed
  File "/etc/side_projects/RCBuilder/rcapp/models.py", line 17
    return "/portal/" + str(self.pk)
                                   ^
TabError: inconsistent use of tabs and spaces in indentation
Unhandled exception in thread started by <function check_errors.<locals>.wrapper at 0x7fe86e393620>
Traceback (most recent call last):
  File "/usr/local/lib/python3.4/dist-packages/django/utils/autoreload.py", line 226, in wrapper
    fn(*args, **kwargs)
  File "/usr/local/lib/python3.4/dist-packages/django/core/management/commands/runserver.py", line 113, in inner_run
    autoreload.raise_last_exception()
  File "/usr/local/lib/python3.4/dist-packages/django/utils/autoreload.py", line 249, in raise_last_exception
    six.reraise(*_exception)
  File "/usr/local/lib/python3.4/dist-packages/django/utils/six.py", line 685, in reraise
    raise value.with_traceback(tb)
  File "/usr/local/lib/python3.4/dist-packages/django/utils/autoreload.py", line 226, in wrapper
    fn(*args, **kwargs)
  File "/usr/local/lib/python3.4/dist-packages/django/__init__.py", line 27, in setup
    apps.populate(settings.INSTALLED_APPS)
  File "/usr/local/lib/python3.4/dist-packages/django/apps/registry.py", line 108, in populate
    app_config.import_models(all_models)
  File "/usr/local/lib/python3.4/dist-packages/django/apps/config.py", line 199, in import_models
    self.models_module = import_module(models_module_name)
  File "/usr/lib/python3.4/importlib/__init__.py", line 109, in import_module
    return _bootstrap._gcd_import(name[level:], package, level)
  File "<frozen importlib._bootstrap>", line 2254, in _gcd_import
  File "<frozen importlib._bootstrap>", line 2237, in _find_and_load
  File "<frozen importlib._bootstrap>", line 2226, in _find_and_load_unlocked
  File "<frozen importlib._bootstrap>", line 1200, in _load_unlocked
  File "<frozen importlib._bootstrap>", line 1129, in _exec
  File "<frozen importlib._bootstrap>", line 1467, in exec_module
  File "<frozen importlib._bootstrap>", line 1572, in get_code
  File "<frozen importlib._bootstrap>", line 1532, in source_to_code
  File "<frozen importlib._bootstrap>", line 321, in _call_with_frames_removed
  File "/etc/side_projects/RCBuilder/rcapp/models.py", line 17
    return "/portal/" + str(self.pk)
                                   ^
TabError: inconsistent use of tabs and spaces in indentation
Unhandled exception in thread started by <function check_errors.<locals>.wrapper at 0x7f9cd40786a8>
Traceback (most recent call last):
  File "/usr/local/lib/python3.4/dist-packages/django/utils/autoreload.py", line 226, in wrapper
    fn(*args, **kwargs)
  File "/usr/local/lib/python3.4/dist-packages/django/core/management/commands/runserver.py", line 113, in inner_run
    autoreload.raise_last_exception()
  File "/usr/local/lib/python3.4/dist-packages/django/utils/autoreload.py", line 249, in raise_last_exception
    six.reraise(*_exception)
  File "/usr/local/lib/python3.4/dist-packages/django/utils/six.py", line 685, in reraise
    raise value.with_traceback(tb)
  File "/usr/local/lib/python3.4/dist-packages/django/utils/autoreload.py", line 226, in wrapper
    fn(*args, **kwargs)
  File "/usr/local/lib/python3.4/dist-packages/django/__init__.py", line 27, in setup
    apps.populate(settings.INSTALLED_APPS)
  File "/usr/local/lib/python3.4/dist-packages/django/apps/registry.py", line 108, in populate
    app_config.import_models(all_models)
  File "/usr/local/lib/python3.4/dist-packages/django/apps/config.py", line 199, in import_models
    self.models_module = import_module(models_module_name)
  File "/usr/lib/python3.4/importlib/__init__.py", line 109, in import_module
    return _bootstrap._gcd_import(name[level:], package, level)
  File "<frozen importlib._bootstrap>", line 2254, in _gcd_import
  File "<frozen importlib._bootstrap>", line 2237, in _find_and_load
  File "<frozen importlib._bootstrap>", line 2226, in _find_and_load_unlocked
  File "<frozen importlib._bootstrap>", line 1200, in _load_unlocked
  File "<frozen importlib._bootstrap>", line 1129, in _exec
  File "<frozen importlib._bootstrap>", line 1467, in exec_module
  File "<frozen importlib._bootstrap>", line 1572, in get_code
  File "<frozen importlib._bootstrap>", line 1532, in source_to_code
  File "<frozen importlib._bootstrap>", line 321, in _call_with_frames_removed
  File "/etc/side_projects/RCBuilder/rcapp/models.py", line 17
    return "/portal/" + str(self.pk)
                                   ^
TabError: inconsistent use of tabs and spaces in indentation
Unhandled exception in thread started by <function check_errors.<locals>.wrapper at 0x7f9103e4e620>
Traceback (most recent call last):
  File "/usr/local/lib/python3.4/dist-packages/django/utils/autoreload.py", line 226, in wrapper
    fn(*args, **kwargs)
  File "/usr/local/lib/python3.4/dist-packages/django/core/management/commands/runserver.py", line 113, in inner_run
    autoreload.raise_last_exception()
  File "/usr/local/lib/python3.4/dist-packages/django/utils/autoreload.py", line 249, in raise_last_exception
    six.reraise(*_exception)
  File "/usr/local/lib/python3.4/dist-packages/django/utils/six.py", line 685, in reraise
    raise value.with_traceback(tb)
  File "/usr/local/lib/python3.4/dist-packages/django/utils/autoreload.py", line 226, in wrapper
    fn(*args, **kwargs)
  File "/usr/local/lib/python3.4/dist-packages/django/__init__.py", line 27, in setup
    apps.populate(settings.INSTALLED_APPS)
  File "/usr/local/lib/python3.4/dist-packages/django/apps/registry.py", line 108, in populate
    app_config.import_models(all_models)
  File "/usr/local/lib/python3.4/dist-packages/django/apps/config.py", line 199, in import_models
    self.models_module = import_module(models_module_name)
  File "/usr/lib/python3.4/importlib/__init__.py", line 109, in import_module
    return _bootstrap._gcd_import(name[level:], package, level)
  File "<frozen importlib._bootstrap>", line 2254, in _gcd_import
  File "<frozen importlib._bootstrap>", line 2237, in _find_and_load
  File "<frozen importlib._bootstrap>", line 2226, in _find_and_load_unlocked
  File "<frozen importlib._bootstrap>", line 1200, in _load_unlocked
  File "<frozen importlib._bootstrap>", line 1129, in _exec
  File "<frozen importlib._bootstrap>", line 1467, in exec_module
  File "<frozen importlib._bootstrap>", line 1572, in get_code
  File "<frozen importlib._bootstrap>", line 1532, in source_to_code
  File "<frozen importlib._bootstrap>", line 321, in _call_with_frames_removed
  File "/etc/side_projects/RCBuilder/rcapp/models.py", line 17
    return "/portal/" + str(self.pk)
                                   ^
TabError: inconsistent use of tabs and spaces in indentation
