Internal Server Error: /
Traceback (most recent call last):
  File "/usr/local/lib/python3.4/dist-packages/django/db/backends/utils.py", line 64, in execute
    return self.cursor.execute(sql, params)
  File "/usr/local/lib/python3.4/dist-packages/django/db/backends/mysql/base.py", line 112, in execute
    return self.cursor.execute(query, args)
  File "/usr/local/lib/python3.4/dist-packages/MySQLdb/cursors.py", line 250, in execute
    self.errorhandler(self, exc, value)
  File "/usr/local/lib/python3.4/dist-packages/MySQLdb/connections.py", line 42, in defaulterrorhandler
    raise errorvalue
  File "/usr/local/lib/python3.4/dist-packages/MySQLdb/cursors.py", line 247, in execute
    res = self._query(query)
  File "/usr/local/lib/python3.4/dist-packages/MySQLdb/cursors.py", line 411, in _query
    rowcount = self._do_query(q)
  File "/usr/local/lib/python3.4/dist-packages/MySQLdb/cursors.py", line 374, in _do_query
    db.query(q)
  File "/usr/local/lib/python3.4/dist-packages/MySQLdb/connections.py", line 270, in query
    _mysql.connection.query(self, query)
_mysql_exceptions.ProgrammingError: (1146, "Table 'rc_builder_app_data.rcb_description' doesn't exist")

The above exception was the direct cause of the following exception:

Traceback (most recent call last):
  File "/usr/local/lib/python3.4/dist-packages/django/core/handlers/exception.py", line 39, in inner
    response = get_response(request)
  File "/usr/local/lib/python3.4/dist-packages/django/core/handlers/base.py", line 217, in _get_response
    response = self.process_exception_by_middleware(e, request)
  File "/usr/local/lib/python3.4/dist-packages/django/core/handlers/base.py", line 215, in _get_response
    response = response.render()
  File "/usr/local/lib/python3.4/dist-packages/django/template/response.py", line 109, in render
    self.content = self.rendered_content
  File "/usr/local/lib/python3.4/dist-packages/django/template/response.py", line 86, in rendered_content
    content = template.render(context, self._request)
  File "/usr/local/lib/python3.4/dist-packages/django/template/backends/django.py", line 66, in render
    return self.template.render(context)
  File "/usr/local/lib/python3.4/dist-packages/django/template/base.py", line 208, in render
    return self._render(context)
  File "/usr/local/lib/python3.4/dist-packages/django/template/base.py", line 199, in _render
    return self.nodelist.render(context)
  File "/usr/local/lib/python3.4/dist-packages/django/template/base.py", line 994, in render
    bit = node.render_annotated(context)
  File "/usr/local/lib/python3.4/dist-packages/django/template/base.py", line 961, in render_annotated
    return self.render(context)
  File "/usr/local/lib/python3.4/dist-packages/django/template/defaulttags.py", line 166, in render
    len_values = len(values)
  File "/usr/local/lib/python3.4/dist-packages/django/db/models/query.py", line 238, in __len__
    self._fetch_all()
  File "/usr/local/lib/python3.4/dist-packages/django/db/models/query.py", line 1085, in _fetch_all
    self._result_cache = list(self.iterator())
  File "/usr/local/lib/python3.4/dist-packages/django/db/models/query.py", line 54, in __iter__
    results = compiler.execute_sql()
  File "/usr/local/lib/python3.4/dist-packages/django/db/models/sql/compiler.py", line 835, in execute_sql
    cursor.execute(sql, params)
  File "/usr/local/lib/python3.4/dist-packages/django/db/backends/utils.py", line 79, in execute
    return super(CursorDebugWrapper, self).execute(sql, params)
  File "/usr/local/lib/python3.4/dist-packages/django/db/backends/utils.py", line 64, in execute
    return self.cursor.execute(sql, params)
  File "/usr/local/lib/python3.4/dist-packages/django/db/utils.py", line 94, in __exit__
    six.reraise(dj_exc_type, dj_exc_value, traceback)
  File "/usr/local/lib/python3.4/dist-packages/django/utils/six.py", line 685, in reraise
    raise value.with_traceback(tb)
  File "/usr/local/lib/python3.4/dist-packages/django/db/backends/utils.py", line 64, in execute
    return self.cursor.execute(sql, params)
  File "/usr/local/lib/python3.4/dist-packages/django/db/backends/mysql/base.py", line 112, in execute
    return self.cursor.execute(query, args)
  File "/usr/local/lib/python3.4/dist-packages/MySQLdb/cursors.py", line 250, in execute
    self.errorhandler(self, exc, value)
  File "/usr/local/lib/python3.4/dist-packages/MySQLdb/connections.py", line 42, in defaulterrorhandler
    raise errorvalue
  File "/usr/local/lib/python3.4/dist-packages/MySQLdb/cursors.py", line 247, in execute
    res = self._query(query)
  File "/usr/local/lib/python3.4/dist-packages/MySQLdb/cursors.py", line 411, in _query
    rowcount = self._do_query(q)
  File "/usr/local/lib/python3.4/dist-packages/MySQLdb/cursors.py", line 374, in _do_query
    db.query(q)
  File "/usr/local/lib/python3.4/dist-packages/MySQLdb/connections.py", line 270, in query
    _mysql.connection.query(self, query)
django.db.utils.ProgrammingError: (1146, "Table 'rc_builder_app_data.rcb_description' doesn't exist")
[05/Dec/2016 10:56:18] "GET / HTTP/1.1" 500 211011
