Unhandled exception in thread started by <function check_errors.<locals>.wrapper at 0x7fabea910378>
Traceback (most recent call last):
  File "/usr/local/lib/python3.4/dist-packages/django/utils/autoreload.py", line 226, in wrapper
    fn(*args, **kwargs)
  File "/usr/local/lib/python3.4/dist-packages/django/core/management/commands/runserver.py", line 121, in inner_run
    self.check(display_num_errors=True)
  File "/usr/local/lib/python3.4/dist-packages/django/core/management/base.py", line 385, in check
    include_deployment_checks=include_deployment_checks,
  File "/usr/local/lib/python3.4/dist-packages/django/core/management/base.py", line 372, in _run_checks
    return checks.run_checks(**kwargs)
  File "/usr/local/lib/python3.4/dist-packages/django/core/checks/registry.py", line 81, in run_checks
    new_errors = check(app_configs=app_configs)
  File "/usr/local/lib/python3.4/dist-packages/django/core/checks/urls.py", line 14, in check_url_config
    return check_resolver(resolver)
  File "/usr/local/lib/python3.4/dist-packages/django/core/checks/urls.py", line 24, in check_resolver
    for pattern in resolver.url_patterns:
  File "/usr/local/lib/python3.4/dist-packages/django/utils/functional.py", line 35, in __get__
    res = instance.__dict__[self.name] = self.func(instance)
  File "/usr/local/lib/python3.4/dist-packages/django/urls/resolvers.py", line 310, in url_patterns
    patterns = getattr(self.urlconf_module, "urlpatterns", self.urlconf_module)
  File "/usr/local/lib/python3.4/dist-packages/django/utils/functional.py", line 35, in __get__
    res = instance.__dict__[self.name] = self.func(instance)
  File "/usr/local/lib/python3.4/dist-packages/django/urls/resolvers.py", line 303, in urlconf_module
    return import_module(self.urlconf_name)
  File "/usr/lib/python3.4/importlib/__init__.py", line 109, in import_module
    return _bootstrap._gcd_import(name[level:], package, level)
  File "<frozen importlib._bootstrap>", line 2254, in _gcd_import
  File "<frozen importlib._bootstrap>", line 2237, in _find_and_load
  File "<frozen importlib._bootstrap>", line 2226, in _find_and_load_unlocked
  File "<frozen importlib._bootstrap>", line 1200, in _load_unlocked
  File "<frozen importlib._bootstrap>", line 1129, in _exec
  File "<frozen importlib._bootstrap>", line 1471, in exec_module
  File "<frozen importlib._bootstrap>", line 321, in _call_with_frames_removed
  File "/etc/side_projects/RCBuilder/RCBuilder/urls.py", line 25, in <module>
    url(r'^portal/', include('rcapp.urls')),
  File "/usr/local/lib/python3.4/dist-packages/django/conf/urls/__init__.py", line 50, in include
    urlconf_module = import_module(urlconf_module)
  File "/usr/lib/python3.4/importlib/__init__.py", line 109, in import_module
    return _bootstrap._gcd_import(name[level:], package, level)
  File "<frozen importlib._bootstrap>", line 2254, in _gcd_import
  File "<frozen importlib._bootstrap>", line 2237, in _find_and_load
  File "<frozen importlib._bootstrap>", line 2226, in _find_and_load_unlocked
  File "<frozen importlib._bootstrap>", line 1200, in _load_unlocked
  File "<frozen importlib._bootstrap>", line 1129, in _exec
  File "<frozen importlib._bootstrap>", line 1471, in exec_module
  File "<frozen importlib._bootstrap>", line 321, in _call_with_frames_removed
  File "/etc/side_projects/RCBuilder/rcapp/urls.py", line 3, in <module>
    from . import views
  File "/etc/side_projects/RCBuilder/rcapp/views.py", line 10, in <module>
    from .forms import RCForm, TargetForm, ResourceForm, ActivityForm, OutputForm, OutcomeForm, ImpactForm, OutputIndicatorForm, OutputPlanFactForm, OutputMethodForm, OutcomeIndicatorForm, OutcomePlanFactForm, OutcomeMethodForm, ImpactIndicatorForm, ImpactPlanFactForm
  File "/etc/side_projects/RCBuilder/rcapp/forms.py", line 44, in <module>
    class TargetForm(forms.ModelForm):
  File "/etc/side_projects/RCBuilder/rcapp/forms.py", line 45, in TargetForm
    class Meta:
  File "/etc/side_projects/RCBuilder/rcapp/forms.py", line 50, in Meta
    for group in groups:
TypeError: 'Manager' object is not iterable
Performing system checks...

Unhandled exception in thread started by <function check_errors.<locals>.wrapper at 0x7f7944809048>
Traceback (most recent call last):
  File "/usr/local/lib/python3.4/dist-packages/django/db/backends/utils.py", line 64, in execute
    return self.cursor.execute(sql, params)
  File "/usr/local/lib/python3.4/dist-packages/django/db/backends/mysql/base.py", line 112, in execute
    return self.cursor.execute(query, args)
  File "/usr/local/lib/python3.4/dist-packages/MySQLdb/cursors.py", line 250, in execute
    self.errorhandler(self, exc, value)
  File "/usr/local/lib/python3.4/dist-packages/MySQLdb/connections.py", line 42, in defaulterrorhandler
    raise errorvalue
  File "/usr/local/lib/python3.4/dist-packages/MySQLdb/cursors.py", line 247, in execute
    res = self._query(query)
  File "/usr/local/lib/python3.4/dist-packages/MySQLdb/cursors.py", line 411, in _query
    rowcount = self._do_query(q)
  File "/usr/local/lib/python3.4/dist-packages/MySQLdb/cursors.py", line 374, in _do_query
    db.query(q)
  File "/usr/local/lib/python3.4/dist-packages/MySQLdb/connections.py", line 270, in query
    _mysql.connection.query(self, query)
_mysql_exceptions.ProgrammingError: (1146, "Table 'rc_builder_app_data.\u0421\u043f\u0438\u0441\u043e\u043a \u0446\u0435\u043b\u0435\u0432\u044b\u0445 \u0433\u0440\u0443\u043f\u043f_targetslistgroup' doesn't exist")

The above exception was the direct cause of the following exception:

Traceback (most recent call last):
  File "/usr/local/lib/python3.4/dist-packages/django/utils/autoreload.py", line 226, in wrapper
    fn(*args, **kwargs)
  File "/usr/local/lib/python3.4/dist-packages/django/core/management/commands/runserver.py", line 121, in inner_run
    self.check(display_num_errors=True)
  File "/usr/local/lib/python3.4/dist-packages/django/core/management/base.py", line 385, in check
    include_deployment_checks=include_deployment_checks,
  File "/usr/local/lib/python3.4/dist-packages/django/core/management/base.py", line 372, in _run_checks
    return checks.run_checks(**kwargs)
  File "/usr/local/lib/python3.4/dist-packages/django/core/checks/registry.py", line 81, in run_checks
    new_errors = check(app_configs=app_configs)
  File "/usr/local/lib/python3.4/dist-packages/django/core/checks/urls.py", line 14, in check_url_config
    return check_resolver(resolver)
  File "/usr/local/lib/python3.4/dist-packages/django/core/checks/urls.py", line 24, in check_resolver
    for pattern in resolver.url_patterns:
  File "/usr/local/lib/python3.4/dist-packages/django/utils/functional.py", line 35, in __get__
    res = instance.__dict__[self.name] = self.func(instance)
  File "/usr/local/lib/python3.4/dist-packages/django/urls/resolvers.py", line 310, in url_patterns
    patterns = getattr(self.urlconf_module, "urlpatterns", self.urlconf_module)
  File "/usr/local/lib/python3.4/dist-packages/django/utils/functional.py", line 35, in __get__
    res = instance.__dict__[self.name] = self.func(instance)
  File "/usr/local/lib/python3.4/dist-packages/django/urls/resolvers.py", line 303, in urlconf_module
    return import_module(self.urlconf_name)
  File "/usr/lib/python3.4/importlib/__init__.py", line 109, in import_module
    return _bootstrap._gcd_import(name[level:], package, level)
  File "<frozen importlib._bootstrap>", line 2254, in _gcd_import
  File "<frozen importlib._bootstrap>", line 2237, in _find_and_load
  File "<frozen importlib._bootstrap>", line 2226, in _find_and_load_unlocked
  File "<frozen importlib._bootstrap>", line 1200, in _load_unlocked
  File "<frozen importlib._bootstrap>", line 1129, in _exec
  File "<frozen importlib._bootstrap>", line 1471, in exec_module
  File "<frozen importlib._bootstrap>", line 321, in _call_with_frames_removed
  File "/etc/side_projects/RCBuilder/RCBuilder/urls.py", line 25, in <module>
    url(r'^portal/', include('rcapp.urls')),
  File "/usr/local/lib/python3.4/dist-packages/django/conf/urls/__init__.py", line 50, in include
    urlconf_module = import_module(urlconf_module)
  File "/usr/lib/python3.4/importlib/__init__.py", line 109, in import_module
    return _bootstrap._gcd_import(name[level:], package, level)
  File "<frozen importlib._bootstrap>", line 2254, in _gcd_import
  File "<frozen importlib._bootstrap>", line 2237, in _find_and_load
  File "<frozen importlib._bootstrap>", line 2226, in _find_and_load_unlocked
  File "<frozen importlib._bootstrap>", line 1200, in _load_unlocked
  File "<frozen importlib._bootstrap>", line 1129, in _exec
  File "<frozen importlib._bootstrap>", line 1471, in exec_module
  File "<frozen importlib._bootstrap>", line 321, in _call_with_frames_removed
  File "/etc/side_projects/RCBuilder/rcapp/urls.py", line 3, in <module>
    from . import views
  File "/etc/side_projects/RCBuilder/rcapp/views.py", line 10, in <module>
    from .forms import RCForm, TargetForm, ResourceForm, ActivityForm, OutputForm, OutcomeForm, ImpactForm, OutputIndicatorForm, OutputPlanFactForm, OutputMethodForm, OutcomeIndicatorForm, OutcomePlanFactForm, OutcomeMethodForm, ImpactIndicatorForm, ImpactPlanFactForm
  File "/etc/side_projects/RCBuilder/rcapp/forms.py", line 44, in <module>
    class TargetForm(forms.ModelForm):
  File "/etc/side_projects/RCBuilder/rcapp/forms.py", line 45, in TargetForm
    class Meta:
  File "/etc/side_projects/RCBuilder/rcapp/forms.py", line 50, in Meta
    for group in groups:
  File "/usr/local/lib/python3.4/dist-packages/django/db/models/query.py", line 256, in __iter__
    self._fetch_all()
  File "/usr/local/lib/python3.4/dist-packages/django/db/models/query.py", line 1085, in _fetch_all
    self._result_cache = list(self.iterator())
  File "/usr/local/lib/python3.4/dist-packages/django/db/models/query.py", line 54, in __iter__
    results = compiler.execute_sql()
  File "/usr/local/lib/python3.4/dist-packages/django/db/models/sql/compiler.py", line 835, in execute_sql
    cursor.execute(sql, params)
  File "/usr/local/lib/python3.4/dist-packages/django/db/backends/utils.py", line 79, in execute
    return super(CursorDebugWrapper, self).execute(sql, params)
  File "/usr/local/lib/python3.4/dist-packages/django/db/backends/utils.py", line 64, in execute
    return self.cursor.execute(sql, params)
  File "/usr/local/lib/python3.4/dist-packages/django/db/utils.py", line 94, in __exit__
    six.reraise(dj_exc_type, dj_exc_value, traceback)
  File "/usr/local/lib/python3.4/dist-packages/django/utils/six.py", line 685, in reraise
    raise value.with_traceback(tb)
  File "/usr/local/lib/python3.4/dist-packages/django/db/backends/utils.py", line 64, in execute
    return self.cursor.execute(sql, params)
  File "/usr/local/lib/python3.4/dist-packages/django/db/backends/mysql/base.py", line 112, in execute
    return self.cursor.execute(query, args)
  File "/usr/local/lib/python3.4/dist-packages/MySQLdb/cursors.py", line 250, in execute
    self.errorhandler(self, exc, value)
  File "/usr/local/lib/python3.4/dist-packages/MySQLdb/connections.py", line 42, in defaulterrorhandler
    raise errorvalue
  File "/usr/local/lib/python3.4/dist-packages/MySQLdb/cursors.py", line 247, in execute
    res = self._query(query)
  File "/usr/local/lib/python3.4/dist-packages/MySQLdb/cursors.py", line 411, in _query
    rowcount = self._do_query(q)
  File "/usr/local/lib/python3.4/dist-packages/MySQLdb/cursors.py", line 374, in _do_query
    db.query(q)
  File "/usr/local/lib/python3.4/dist-packages/MySQLdb/connections.py", line 270, in query
    _mysql.connection.query(self, query)
django.db.utils.ProgrammingError: (1146, "Table 'rc_builder_app_data.\u0421\u043f\u0438\u0441\u043e\u043a \u0446\u0435\u043b\u0435\u0432\u044b\u0445 \u0433\u0440\u0443\u043f\u043f_targetslistgroup' doesn't exist")
Performing system checks...

Unhandled exception in thread started by <function check_errors.<locals>.wrapper at 0x7f0779434378>
Traceback (most recent call last):
  File "/usr/local/lib/python3.4/dist-packages/django/db/backends/utils.py", line 64, in execute
    return self.cursor.execute(sql, params)
  File "/usr/local/lib/python3.4/dist-packages/django/db/backends/mysql/base.py", line 112, in execute
    return self.cursor.execute(query, args)
  File "/usr/local/lib/python3.4/dist-packages/MySQLdb/cursors.py", line 250, in execute
    self.errorhandler(self, exc, value)
  File "/usr/local/lib/python3.4/dist-packages/MySQLdb/connections.py", line 42, in defaulterrorhandler
    raise errorvalue
  File "/usr/local/lib/python3.4/dist-packages/MySQLdb/cursors.py", line 247, in execute
    res = self._query(query)
  File "/usr/local/lib/python3.4/dist-packages/MySQLdb/cursors.py", line 411, in _query
    rowcount = self._do_query(q)
  File "/usr/local/lib/python3.4/dist-packages/MySQLdb/cursors.py", line 374, in _do_query
    db.query(q)
  File "/usr/local/lib/python3.4/dist-packages/MySQLdb/connections.py", line 270, in query
    _mysql.connection.query(self, query)
_mysql_exceptions.ProgrammingError: (1146, "Table 'rc_builder_app_data.\u0421\u043f\u0438\u0441\u043e\u043a \u0446\u0435\u043b\u0435\u0432\u044b\u0445 \u0433\u0440\u0443\u043f\u043f_targetslistgroup' doesn't exist")

The above exception was the direct cause of the following exception:

Traceback (most recent call last):
  File "/usr/local/lib/python3.4/dist-packages/django/utils/autoreload.py", line 226, in wrapper
    fn(*args, **kwargs)
  File "/usr/local/lib/python3.4/dist-packages/django/core/management/commands/runserver.py", line 121, in inner_run
    self.check(display_num_errors=True)
  File "/usr/local/lib/python3.4/dist-packages/django/core/management/base.py", line 385, in check
    include_deployment_checks=include_deployment_checks,
  File "/usr/local/lib/python3.4/dist-packages/django/core/management/base.py", line 372, in _run_checks
    return checks.run_checks(**kwargs)
  File "/usr/local/lib/python3.4/dist-packages/django/core/checks/registry.py", line 81, in run_checks
    new_errors = check(app_configs=app_configs)
  File "/usr/local/lib/python3.4/dist-packages/django/core/checks/urls.py", line 14, in check_url_config
    return check_resolver(resolver)
  File "/usr/local/lib/python3.4/dist-packages/django/core/checks/urls.py", line 24, in check_resolver
    for pattern in resolver.url_patterns:
  File "/usr/local/lib/python3.4/dist-packages/django/utils/functional.py", line 35, in __get__
    res = instance.__dict__[self.name] = self.func(instance)
  File "/usr/local/lib/python3.4/dist-packages/django/urls/resolvers.py", line 310, in url_patterns
    patterns = getattr(self.urlconf_module, "urlpatterns", self.urlconf_module)
  File "/usr/local/lib/python3.4/dist-packages/django/utils/functional.py", line 35, in __get__
    res = instance.__dict__[self.name] = self.func(instance)
  File "/usr/local/lib/python3.4/dist-packages/django/urls/resolvers.py", line 303, in urlconf_module
    return import_module(self.urlconf_name)
  File "/usr/lib/python3.4/importlib/__init__.py", line 109, in import_module
    return _bootstrap._gcd_import(name[level:], package, level)
  File "<frozen importlib._bootstrap>", line 2254, in _gcd_import
  File "<frozen importlib._bootstrap>", line 2237, in _find_and_load
  File "<frozen importlib._bootstrap>", line 2226, in _find_and_load_unlocked
  File "<frozen importlib._bootstrap>", line 1200, in _load_unlocked
  File "<frozen importlib._bootstrap>", line 1129, in _exec
  File "<frozen importlib._bootstrap>", line 1471, in exec_module
  File "<frozen importlib._bootstrap>", line 321, in _call_with_frames_removed
  File "/etc/side_projects/RCBuilder/RCBuilder/urls.py", line 25, in <module>
    url(r'^portal/', include('rcapp.urls')),
  File "/usr/local/lib/python3.4/dist-packages/django/conf/urls/__init__.py", line 50, in include
    urlconf_module = import_module(urlconf_module)
  File "/usr/lib/python3.4/importlib/__init__.py", line 109, in import_module
    return _bootstrap._gcd_import(name[level:], package, level)
  File "<frozen importlib._bootstrap>", line 2254, in _gcd_import
  File "<frozen importlib._bootstrap>", line 2237, in _find_and_load
  File "<frozen importlib._bootstrap>", line 2226, in _find_and_load_unlocked
  File "<frozen importlib._bootstrap>", line 1200, in _load_unlocked
  File "<frozen importlib._bootstrap>", line 1129, in _exec
  File "<frozen importlib._bootstrap>", line 1471, in exec_module
  File "<frozen importlib._bootstrap>", line 321, in _call_with_frames_removed
  File "/etc/side_projects/RCBuilder/rcapp/urls.py", line 3, in <module>
    from . import views
  File "/etc/side_projects/RCBuilder/rcapp/views.py", line 10, in <module>
    from .forms import RCForm, TargetForm, ResourceForm, ActivityForm, OutputForm, OutcomeForm, ImpactForm, OutputIndicatorForm, OutputPlanFactForm, OutputMethodForm, OutcomeIndicatorForm, OutcomePlanFactForm, OutcomeMethodForm, ImpactIndicatorForm, ImpactPlanFactForm
  File "/etc/side_projects/RCBuilder/rcapp/forms.py", line 44, in <module>
    class TargetForm(forms.ModelForm):
  File "/etc/side_projects/RCBuilder/rcapp/forms.py", line 45, in TargetForm
    class Meta:
  File "/etc/side_projects/RCBuilder/rcapp/forms.py", line 50, in Meta
    for group in groups:
  File "/usr/local/lib/python3.4/dist-packages/django/db/models/query.py", line 256, in __iter__
    self._fetch_all()
  File "/usr/local/lib/python3.4/dist-packages/django/db/models/query.py", line 1085, in _fetch_all
    self._result_cache = list(self.iterator())
  File "/usr/local/lib/python3.4/dist-packages/django/db/models/query.py", line 54, in __iter__
    results = compiler.execute_sql()
  File "/usr/local/lib/python3.4/dist-packages/django/db/models/sql/compiler.py", line 835, in execute_sql
    cursor.execute(sql, params)
  File "/usr/local/lib/python3.4/dist-packages/django/db/backends/utils.py", line 79, in execute
    return super(CursorDebugWrapper, self).execute(sql, params)
  File "/usr/local/lib/python3.4/dist-packages/django/db/backends/utils.py", line 64, in execute
    return self.cursor.execute(sql, params)
  File "/usr/local/lib/python3.4/dist-packages/django/db/utils.py", line 94, in __exit__
    six.reraise(dj_exc_type, dj_exc_value, traceback)
  File "/usr/local/lib/python3.4/dist-packages/django/utils/six.py", line 685, in reraise
    raise value.with_traceback(tb)
  File "/usr/local/lib/python3.4/dist-packages/django/db/backends/utils.py", line 64, in execute
    return self.cursor.execute(sql, params)
  File "/usr/local/lib/python3.4/dist-packages/django/db/backends/mysql/base.py", line 112, in execute
    return self.cursor.execute(query, args)
  File "/usr/local/lib/python3.4/dist-packages/MySQLdb/cursors.py", line 250, in execute
    self.errorhandler(self, exc, value)
  File "/usr/local/lib/python3.4/dist-packages/MySQLdb/connections.py", line 42, in defaulterrorhandler
    raise errorvalue
  File "/usr/local/lib/python3.4/dist-packages/MySQLdb/cursors.py", line 247, in execute
    res = self._query(query)
  File "/usr/local/lib/python3.4/dist-packages/MySQLdb/cursors.py", line 411, in _query
    rowcount = self._do_query(q)
  File "/usr/local/lib/python3.4/dist-packages/MySQLdb/cursors.py", line 374, in _do_query
    db.query(q)
  File "/usr/local/lib/python3.4/dist-packages/MySQLdb/connections.py", line 270, in query
    _mysql.connection.query(self, query)
django.db.utils.ProgrammingError: (1146, "Table 'rc_builder_app_data.\u0421\u043f\u0438\u0441\u043e\u043a \u0446\u0435\u043b\u0435\u0432\u044b\u0445 \u0433\u0440\u0443\u043f\u043f_targetslistgroup' doesn't exist")
Performing system checks...

Unhandled exception in thread started by <function check_errors.<locals>.wrapper at 0x7f7806959378>
Traceback (most recent call last):
  File "/usr/local/lib/python3.4/dist-packages/django/utils/autoreload.py", line 226, in wrapper
    fn(*args, **kwargs)
  File "/usr/local/lib/python3.4/dist-packages/django/core/management/commands/runserver.py", line 121, in inner_run
    self.check(display_num_errors=True)
  File "/usr/local/lib/python3.4/dist-packages/django/core/management/base.py", line 385, in check
    include_deployment_checks=include_deployment_checks,
  File "/usr/local/lib/python3.4/dist-packages/django/core/management/base.py", line 372, in _run_checks
    return checks.run_checks(**kwargs)
  File "/usr/local/lib/python3.4/dist-packages/django/core/checks/registry.py", line 81, in run_checks
    new_errors = check(app_configs=app_configs)
  File "/usr/local/lib/python3.4/dist-packages/django/core/checks/urls.py", line 14, in check_url_config
    return check_resolver(resolver)
  File "/usr/local/lib/python3.4/dist-packages/django/core/checks/urls.py", line 24, in check_resolver
    for pattern in resolver.url_patterns:
  File "/usr/local/lib/python3.4/dist-packages/django/utils/functional.py", line 35, in __get__
    res = instance.__dict__[self.name] = self.func(instance)
  File "/usr/local/lib/python3.4/dist-packages/django/urls/resolvers.py", line 310, in url_patterns
    patterns = getattr(self.urlconf_module, "urlpatterns", self.urlconf_module)
  File "/usr/local/lib/python3.4/dist-packages/django/utils/functional.py", line 35, in __get__
    res = instance.__dict__[self.name] = self.func(instance)
  File "/usr/local/lib/python3.4/dist-packages/django/urls/resolvers.py", line 303, in urlconf_module
    return import_module(self.urlconf_name)
  File "/usr/lib/python3.4/importlib/__init__.py", line 109, in import_module
    return _bootstrap._gcd_import(name[level:], package, level)
  File "<frozen importlib._bootstrap>", line 2254, in _gcd_import
  File "<frozen importlib._bootstrap>", line 2237, in _find_and_load
  File "<frozen importlib._bootstrap>", line 2226, in _find_and_load_unlocked
  File "<frozen importlib._bootstrap>", line 1200, in _load_unlocked
  File "<frozen importlib._bootstrap>", line 1129, in _exec
  File "<frozen importlib._bootstrap>", line 1471, in exec_module
  File "<frozen importlib._bootstrap>", line 321, in _call_with_frames_removed
  File "/etc/side_projects/RCBuilder/RCBuilder/urls.py", line 25, in <module>
    url(r'^portal/', include('rcapp.urls')),
  File "/usr/local/lib/python3.4/dist-packages/django/conf/urls/__init__.py", line 50, in include
    urlconf_module = import_module(urlconf_module)
  File "/usr/lib/python3.4/importlib/__init__.py", line 109, in import_module
    return _bootstrap._gcd_import(name[level:], package, level)
  File "<frozen importlib._bootstrap>", line 2254, in _gcd_import
  File "<frozen importlib._bootstrap>", line 2237, in _find_and_load
  File "<frozen importlib._bootstrap>", line 2226, in _find_and_load_unlocked
  File "<frozen importlib._bootstrap>", line 1200, in _load_unlocked
  File "<frozen importlib._bootstrap>", line 1129, in _exec
  File "<frozen importlib._bootstrap>", line 1471, in exec_module
  File "<frozen importlib._bootstrap>", line 321, in _call_with_frames_removed
  File "/etc/side_projects/RCBuilder/rcapp/urls.py", line 3, in <module>
    from . import views
  File "/etc/side_projects/RCBuilder/rcapp/views.py", line 10, in <module>
    from .forms import RCForm, TargetForm, ResourceForm, ActivityForm, OutputForm, OutcomeForm, ImpactForm, OutputIndicatorForm, OutputPlanFactForm, OutputMethodForm, OutcomeIndicatorForm, OutcomePlanFactForm, OutcomeMethodForm, ImpactIndicatorForm, ImpactPlanFactForm
  File "/etc/side_projects/RCBuilder/rcapp/forms.py", line 44, in <module>
    class TargetForm(forms.ModelForm):
  File "/etc/side_projects/RCBuilder/rcapp/forms.py", line 45, in TargetForm
    class Meta:
  File "/etc/side_projects/RCBuilder/rcapp/forms.py", line 48, in Meta
    groups = TargetsListGroup.objects.all()
NameError: name 'TargetsListGroup' is not defined
Performing system checks...

Unhandled exception in thread started by <function check_errors.<locals>.wrapper at 0x7f205bb08378>
Traceback (most recent call last):
  File "/usr/local/lib/python3.4/dist-packages/django/utils/autoreload.py", line 226, in wrapper
    fn(*args, **kwargs)
  File "/usr/local/lib/python3.4/dist-packages/django/core/management/commands/runserver.py", line 121, in inner_run
    self.check(display_num_errors=True)
  File "/usr/local/lib/python3.4/dist-packages/django/core/management/base.py", line 385, in check
    include_deployment_checks=include_deployment_checks,
  File "/usr/local/lib/python3.4/dist-packages/django/core/management/base.py", line 372, in _run_checks
    return checks.run_checks(**kwargs)
  File "/usr/local/lib/python3.4/dist-packages/django/core/checks/registry.py", line 81, in run_checks
    new_errors = check(app_configs=app_configs)
  File "/usr/local/lib/python3.4/dist-packages/django/core/checks/urls.py", line 14, in check_url_config
    return check_resolver(resolver)
  File "/usr/local/lib/python3.4/dist-packages/django/core/checks/urls.py", line 24, in check_resolver
    for pattern in resolver.url_patterns:
  File "/usr/local/lib/python3.4/dist-packages/django/utils/functional.py", line 35, in __get__
    res = instance.__dict__[self.name] = self.func(instance)
  File "/usr/local/lib/python3.4/dist-packages/django/urls/resolvers.py", line 310, in url_patterns
    patterns = getattr(self.urlconf_module, "urlpatterns", self.urlconf_module)
  File "/usr/local/lib/python3.4/dist-packages/django/utils/functional.py", line 35, in __get__
    res = instance.__dict__[self.name] = self.func(instance)
  File "/usr/local/lib/python3.4/dist-packages/django/urls/resolvers.py", line 303, in urlconf_module
    return import_module(self.urlconf_name)
  File "/usr/lib/python3.4/importlib/__init__.py", line 109, in import_module
    return _bootstrap._gcd_import(name[level:], package, level)
  File "<frozen importlib._bootstrap>", line 2254, in _gcd_import
  File "<frozen importlib._bootstrap>", line 2237, in _find_and_load
  File "<frozen importlib._bootstrap>", line 2226, in _find_and_load_unlocked
  File "<frozen importlib._bootstrap>", line 1200, in _load_unlocked
  File "<frozen importlib._bootstrap>", line 1129, in _exec
  File "<frozen importlib._bootstrap>", line 1471, in exec_module
  File "<frozen importlib._bootstrap>", line 321, in _call_with_frames_removed
  File "/etc/side_projects/RCBuilder/RCBuilder/urls.py", line 25, in <module>
    url(r'^portal/', include('rcapp.urls')),
  File "/usr/local/lib/python3.4/dist-packages/django/conf/urls/__init__.py", line 50, in include
    urlconf_module = import_module(urlconf_module)
  File "/usr/lib/python3.4/importlib/__init__.py", line 109, in import_module
    return _bootstrap._gcd_import(name[level:], package, level)
  File "<frozen importlib._bootstrap>", line 2254, in _gcd_import
  File "<frozen importlib._bootstrap>", line 2237, in _find_and_load
  File "<frozen importlib._bootstrap>", line 2226, in _find_and_load_unlocked
  File "<frozen importlib._bootstrap>", line 1200, in _load_unlocked
  File "<frozen importlib._bootstrap>", line 1129, in _exec
  File "<frozen importlib._bootstrap>", line 1471, in exec_module
  File "<frozen importlib._bootstrap>", line 321, in _call_with_frames_removed
  File "/etc/side_projects/RCBuilder/rcapp/urls.py", line 3, in <module>
    from . import views
  File "/etc/side_projects/RCBuilder/rcapp/views.py", line 10, in <module>
    from .forms import RCForm, TargetForm, ResourceForm, ActivityForm, OutputForm, OutcomeForm, ImpactForm, OutputIndicatorForm, OutputPlanFactForm, OutputMethodForm, OutcomeIndicatorForm, OutcomePlanFactForm, OutcomeMethodForm, ImpactIndicatorForm, ImpactPlanFactForm
  File "/etc/side_projects/RCBuilder/rcapp/forms.py", line 44, in <module>
    class TargetForm(forms.ModelForm):
  File "/etc/side_projects/RCBuilder/rcapp/forms.py", line 45, in TargetForm
    class Meta:
  File "/etc/side_projects/RCBuilder/rcapp/forms.py", line 48, in Meta
    groups = TargetsListGroup.objects.all()
NameError: name 'TargetsListGroup' is not defined
Performing system checks...

Performing system checks...

System check identified no issues (0 silenced).
December 14, 2016 - 01:13:46
Django version 1.10, using settings 'RCBuilder.settings'
Starting development server at http://0.0.0.0:8080/
Quit the server with CONTROL-C.
Performing system checks...

System check identified no issues (0 silenced).
December 14, 2016 - 01:13:52
Django version 1.10, using settings 'RCBuilder.settings'
Starting development server at http://0.0.0.0:8080/
Quit the server with CONTROL-C.
Unhandled exception in thread started by <function check_errors.<locals>.wrapper at 0x7f7e33986048>
Traceback (most recent call last):
  File "/usr/local/lib/python3.4/dist-packages/django/db/backends/utils.py", line 64, in execute
    return self.cursor.execute(sql, params)
  File "/usr/local/lib/python3.4/dist-packages/django/db/backends/mysql/base.py", line 112, in execute
    return self.cursor.execute(query, args)
  File "/usr/local/lib/python3.4/dist-packages/MySQLdb/cursors.py", line 250, in execute
    self.errorhandler(self, exc, value)
  File "/usr/local/lib/python3.4/dist-packages/MySQLdb/connections.py", line 42, in defaulterrorhandler
    raise errorvalue
  File "/usr/local/lib/python3.4/dist-packages/MySQLdb/cursors.py", line 247, in execute
    res = self._query(query)
  File "/usr/local/lib/python3.4/dist-packages/MySQLdb/cursors.py", line 411, in _query
    rowcount = self._do_query(q)
  File "/usr/local/lib/python3.4/dist-packages/MySQLdb/cursors.py", line 374, in _do_query
    db.query(q)
  File "/usr/local/lib/python3.4/dist-packages/MySQLdb/connections.py", line 270, in query
    _mysql.connection.query(self, query)
_mysql_exceptions.ProgrammingError: (1146, "Table 'rc_builder_app_data.\u0421\u043f\u0438\u0441\u043e\u043a \u0446\u0435\u043b\u0435\u0432\u044b\u0445 \u0433\u0440\u0443\u043f\u043f_targetslistgroup' doesn't exist")

The above exception was the direct cause of the following exception:

Traceback (most recent call last):
  File "/usr/local/lib/python3.4/dist-packages/django/utils/autoreload.py", line 226, in wrapper
    fn(*args, **kwargs)
  File "/usr/local/lib/python3.4/dist-packages/django/core/management/commands/runserver.py", line 121, in inner_run
    self.check(display_num_errors=True)
  File "/usr/local/lib/python3.4/dist-packages/django/core/management/base.py", line 385, in check
    include_deployment_checks=include_deployment_checks,
  File "/usr/local/lib/python3.4/dist-packages/django/core/management/base.py", line 372, in _run_checks
    return checks.run_checks(**kwargs)
  File "/usr/local/lib/python3.4/dist-packages/django/core/checks/registry.py", line 81, in run_checks
    new_errors = check(app_configs=app_configs)
  File "/usr/local/lib/python3.4/dist-packages/django/core/checks/urls.py", line 14, in check_url_config
    return check_resolver(resolver)
  File "/usr/local/lib/python3.4/dist-packages/django/core/checks/urls.py", line 24, in check_resolver
    for pattern in resolver.url_patterns:
  File "/usr/local/lib/python3.4/dist-packages/django/utils/functional.py", line 35, in __get__
    res = instance.__dict__[self.name] = self.func(instance)
  File "/usr/local/lib/python3.4/dist-packages/django/urls/resolvers.py", line 310, in url_patterns
    patterns = getattr(self.urlconf_module, "urlpatterns", self.urlconf_module)
  File "/usr/local/lib/python3.4/dist-packages/django/utils/functional.py", line 35, in __get__
    res = instance.__dict__[self.name] = self.func(instance)
  File "/usr/local/lib/python3.4/dist-packages/django/urls/resolvers.py", line 303, in urlconf_module
    return import_module(self.urlconf_name)
  File "/usr/lib/python3.4/importlib/__init__.py", line 109, in import_module
    return _bootstrap._gcd_import(name[level:], package, level)
  File "<frozen importlib._bootstrap>", line 2254, in _gcd_import
  File "<frozen importlib._bootstrap>", line 2237, in _find_and_load
  File "<frozen importlib._bootstrap>", line 2226, in _find_and_load_unlocked
  File "<frozen importlib._bootstrap>", line 1200, in _load_unlocked
  File "<frozen importlib._bootstrap>", line 1129, in _exec
  File "<frozen importlib._bootstrap>", line 1471, in exec_module
  File "<frozen importlib._bootstrap>", line 321, in _call_with_frames_removed
  File "/etc/side_projects/RCBuilder/RCBuilder/urls.py", line 25, in <module>
    url(r'^portal/', include('rcapp.urls')),
  File "/usr/local/lib/python3.4/dist-packages/django/conf/urls/__init__.py", line 50, in include
    urlconf_module = import_module(urlconf_module)
  File "/usr/lib/python3.4/importlib/__init__.py", line 109, in import_module
    return _bootstrap._gcd_import(name[level:], package, level)
  File "<frozen importlib._bootstrap>", line 2254, in _gcd_import
  File "<frozen importlib._bootstrap>", line 2237, in _find_and_load
  File "<frozen importlib._bootstrap>", line 2226, in _find_and_load_unlocked
  File "<frozen importlib._bootstrap>", line 1200, in _load_unlocked
  File "<frozen importlib._bootstrap>", line 1129, in _exec
  File "<frozen importlib._bootstrap>", line 1471, in exec_module
  File "<frozen importlib._bootstrap>", line 321, in _call_with_frames_removed
  File "/etc/side_projects/RCBuilder/rcapp/urls.py", line 3, in <module>
    from . import views
  File "/etc/side_projects/RCBuilder/rcapp/views.py", line 10, in <module>
    from .forms import RCForm, TargetForm, ResourceForm, ActivityForm, OutputForm, OutcomeForm, ImpactForm, OutputIndicatorForm, OutputPlanFactForm, OutputMethodForm, OutcomeIndicatorForm, OutcomePlanFactForm, OutcomeMethodForm, ImpactIndicatorForm, ImpactPlanFactForm
  File "/etc/side_projects/RCBuilder/rcapp/forms.py", line 44, in <module>
    class TargetForm(forms.ModelForm):
  File "/etc/side_projects/RCBuilder/rcapp/forms.py", line 45, in TargetForm
    class Meta:
  File "/etc/side_projects/RCBuilder/rcapp/forms.py", line 50, in Meta
    for group in groups:
  File "/usr/local/lib/python3.4/dist-packages/django/db/models/query.py", line 256, in __iter__
    self._fetch_all()
  File "/usr/local/lib/python3.4/dist-packages/django/db/models/query.py", line 1085, in _fetch_all
    self._result_cache = list(self.iterator())
  File "/usr/local/lib/python3.4/dist-packages/django/db/models/query.py", line 54, in __iter__
    results = compiler.execute_sql()
  File "/usr/local/lib/python3.4/dist-packages/django/db/models/sql/compiler.py", line 835, in execute_sql
    cursor.execute(sql, params)
  File "/usr/local/lib/python3.4/dist-packages/django/db/backends/utils.py", line 79, in execute
    return super(CursorDebugWrapper, self).execute(sql, params)
  File "/usr/local/lib/python3.4/dist-packages/django/db/backends/utils.py", line 64, in execute
    return self.cursor.execute(sql, params)
  File "/usr/local/lib/python3.4/dist-packages/django/db/utils.py", line 94, in __exit__
    six.reraise(dj_exc_type, dj_exc_value, traceback)
  File "/usr/local/lib/python3.4/dist-packages/django/utils/six.py", line 685, in reraise
    raise value.with_traceback(tb)
  File "/usr/local/lib/python3.4/dist-packages/django/db/backends/utils.py", line 64, in execute
    return self.cursor.execute(sql, params)
  File "/usr/local/lib/python3.4/dist-packages/django/db/backends/mysql/base.py", line 112, in execute
    return self.cursor.execute(query, args)
  File "/usr/local/lib/python3.4/dist-packages/MySQLdb/cursors.py", line 250, in execute
    self.errorhandler(self, exc, value)
  File "/usr/local/lib/python3.4/dist-packages/MySQLdb/connections.py", line 42, in defaulterrorhandler
    raise errorvalue
  File "/usr/local/lib/python3.4/dist-packages/MySQLdb/cursors.py", line 247, in execute
    res = self._query(query)
  File "/usr/local/lib/python3.4/dist-packages/MySQLdb/cursors.py", line 411, in _query
    rowcount = self._do_query(q)
  File "/usr/local/lib/python3.4/dist-packages/MySQLdb/cursors.py", line 374, in _do_query
    db.query(q)
  File "/usr/local/lib/python3.4/dist-packages/MySQLdb/connections.py", line 270, in query
    _mysql.connection.query(self, query)
django.db.utils.ProgrammingError: (1146, "Table 'rc_builder_app_data.\u0421\u043f\u0438\u0441\u043e\u043a \u0446\u0435\u043b\u0435\u0432\u044b\u0445 \u0433\u0440\u0443\u043f\u043f_targetslistgroup' doesn't exist")
Performing system checks...

Unhandled exception in thread started by <function check_errors.<locals>.wrapper at 0x7fad791e4378>
Traceback (most recent call last):
  File "/usr/local/lib/python3.4/dist-packages/django/db/backends/utils.py", line 64, in execute
    return self.cursor.execute(sql, params)
  File "/usr/local/lib/python3.4/dist-packages/django/db/backends/mysql/base.py", line 112, in execute
    return self.cursor.execute(query, args)
  File "/usr/local/lib/python3.4/dist-packages/MySQLdb/cursors.py", line 250, in execute
    self.errorhandler(self, exc, value)
  File "/usr/local/lib/python3.4/dist-packages/MySQLdb/connections.py", line 42, in defaulterrorhandler
    raise errorvalue
  File "/usr/local/lib/python3.4/dist-packages/MySQLdb/cursors.py", line 247, in execute
    res = self._query(query)
  File "/usr/local/lib/python3.4/dist-packages/MySQLdb/cursors.py", line 411, in _query
    rowcount = self._do_query(q)
  File "/usr/local/lib/python3.4/dist-packages/MySQLdb/cursors.py", line 374, in _do_query
    db.query(q)
  File "/usr/local/lib/python3.4/dist-packages/MySQLdb/connections.py", line 270, in query
    _mysql.connection.query(self, query)
_mysql_exceptions.ProgrammingError: (1146, "Table 'rc_builder_app_data.\u0421\u043f\u0438\u0441\u043e\u043a \u0446\u0435\u043b\u0435\u0432\u044b\u0445 \u0433\u0440\u0443\u043f\u043f_targetslistgroup' doesn't exist")

The above exception was the direct cause of the following exception:

Traceback (most recent call last):
  File "/usr/local/lib/python3.4/dist-packages/django/utils/autoreload.py", line 226, in wrapper
    fn(*args, **kwargs)
  File "/usr/local/lib/python3.4/dist-packages/django/core/management/commands/runserver.py", line 121, in inner_run
    self.check(display_num_errors=True)
  File "/usr/local/lib/python3.4/dist-packages/django/core/management/base.py", line 385, in check
    include_deployment_checks=include_deployment_checks,
  File "/usr/local/lib/python3.4/dist-packages/django/core/management/base.py", line 372, in _run_checks
    return checks.run_checks(**kwargs)
  File "/usr/local/lib/python3.4/dist-packages/django/core/checks/registry.py", line 81, in run_checks
    new_errors = check(app_configs=app_configs)
  File "/usr/local/lib/python3.4/dist-packages/django/core/checks/urls.py", line 14, in check_url_config
    return check_resolver(resolver)
  File "/usr/local/lib/python3.4/dist-packages/django/core/checks/urls.py", line 24, in check_resolver
    for pattern in resolver.url_patterns:
  File "/usr/local/lib/python3.4/dist-packages/django/utils/functional.py", line 35, in __get__
    res = instance.__dict__[self.name] = self.func(instance)
  File "/usr/local/lib/python3.4/dist-packages/django/urls/resolvers.py", line 310, in url_patterns
    patterns = getattr(self.urlconf_module, "urlpatterns", self.urlconf_module)
  File "/usr/local/lib/python3.4/dist-packages/django/utils/functional.py", line 35, in __get__
    res = instance.__dict__[self.name] = self.func(instance)
  File "/usr/local/lib/python3.4/dist-packages/django/urls/resolvers.py", line 303, in urlconf_module
    return import_module(self.urlconf_name)
  File "/usr/lib/python3.4/importlib/__init__.py", line 109, in import_module
    return _bootstrap._gcd_import(name[level:], package, level)
  File "<frozen importlib._bootstrap>", line 2254, in _gcd_import
  File "<frozen importlib._bootstrap>", line 2237, in _find_and_load
  File "<frozen importlib._bootstrap>", line 2226, in _find_and_load_unlocked
  File "<frozen importlib._bootstrap>", line 1200, in _load_unlocked
  File "<frozen importlib._bootstrap>", line 1129, in _exec
  File "<frozen importlib._bootstrap>", line 1471, in exec_module
  File "<frozen importlib._bootstrap>", line 321, in _call_with_frames_removed
  File "/etc/side_projects/RCBuilder/RCBuilder/urls.py", line 25, in <module>
    url(r'^portal/', include('rcapp.urls')),
  File "/usr/local/lib/python3.4/dist-packages/django/conf/urls/__init__.py", line 50, in include
    urlconf_module = import_module(urlconf_module)
  File "/usr/lib/python3.4/importlib/__init__.py", line 109, in import_module
    return _bootstrap._gcd_import(name[level:], package, level)
  File "<frozen importlib._bootstrap>", line 2254, in _gcd_import
  File "<frozen importlib._bootstrap>", line 2237, in _find_and_load
  File "<frozen importlib._bootstrap>", line 2226, in _find_and_load_unlocked
  File "<frozen importlib._bootstrap>", line 1200, in _load_unlocked
  File "<frozen importlib._bootstrap>", line 1129, in _exec
  File "<frozen importlib._bootstrap>", line 1471, in exec_module
  File "<frozen importlib._bootstrap>", line 321, in _call_with_frames_removed
  File "/etc/side_projects/RCBuilder/rcapp/urls.py", line 3, in <module>
    from . import views
  File "/etc/side_projects/RCBuilder/rcapp/views.py", line 10, in <module>
    from .forms import RCForm, TargetForm, ResourceForm, ActivityForm, OutputForm, OutcomeForm, ImpactForm, OutputIndicatorForm, OutputPlanFactForm, OutputMethodForm, OutcomeIndicatorForm, OutcomePlanFactForm, OutcomeMethodForm, ImpactIndicatorForm, ImpactPlanFactForm
  File "/etc/side_projects/RCBuilder/rcapp/forms.py", line 44, in <module>
    class TargetForm(forms.ModelForm):
  File "/etc/side_projects/RCBuilder/rcapp/forms.py", line 45, in TargetForm
    class Meta:
  File "/etc/side_projects/RCBuilder/rcapp/forms.py", line 50, in Meta
    for group in groups:
  File "/usr/local/lib/python3.4/dist-packages/django/db/models/query.py", line 256, in __iter__
    self._fetch_all()
  File "/usr/local/lib/python3.4/dist-packages/django/db/models/query.py", line 1085, in _fetch_all
    self._result_cache = list(self.iterator())
  File "/usr/local/lib/python3.4/dist-packages/django/db/models/query.py", line 54, in __iter__
    results = compiler.execute_sql()
  File "/usr/local/lib/python3.4/dist-packages/django/db/models/sql/compiler.py", line 835, in execute_sql
    cursor.execute(sql, params)
  File "/usr/local/lib/python3.4/dist-packages/django/db/backends/utils.py", line 79, in execute
    return super(CursorDebugWrapper, self).execute(sql, params)
  File "/usr/local/lib/python3.4/dist-packages/django/db/backends/utils.py", line 64, in execute
    return self.cursor.execute(sql, params)
  File "/usr/local/lib/python3.4/dist-packages/django/db/utils.py", line 94, in __exit__
    six.reraise(dj_exc_type, dj_exc_value, traceback)
  File "/usr/local/lib/python3.4/dist-packages/django/utils/six.py", line 685, in reraise
    raise value.with_traceback(tb)
  File "/usr/local/lib/python3.4/dist-packages/django/db/backends/utils.py", line 64, in execute
    return self.cursor.execute(sql, params)
  File "/usr/local/lib/python3.4/dist-packages/django/db/backends/mysql/base.py", line 112, in execute
    return self.cursor.execute(query, args)
  File "/usr/local/lib/python3.4/dist-packages/MySQLdb/cursors.py", line 250, in execute
    self.errorhandler(self, exc, value)
  File "/usr/local/lib/python3.4/dist-packages/MySQLdb/connections.py", line 42, in defaulterrorhandler
    raise errorvalue
  File "/usr/local/lib/python3.4/dist-packages/MySQLdb/cursors.py", line 247, in execute
    res = self._query(query)
  File "/usr/local/lib/python3.4/dist-packages/MySQLdb/cursors.py", line 411, in _query
    rowcount = self._do_query(q)
  File "/usr/local/lib/python3.4/dist-packages/MySQLdb/cursors.py", line 374, in _do_query
    db.query(q)
  File "/usr/local/lib/python3.4/dist-packages/MySQLdb/connections.py", line 270, in query
    _mysql.connection.query(self, query)
django.db.utils.ProgrammingError: (1146, "Table 'rc_builder_app_data.\u0421\u043f\u0438\u0441\u043e\u043a \u0446\u0435\u043b\u0435\u0432\u044b\u0445 \u0433\u0440\u0443\u043f\u043f_targetslistgroup' doesn't exist")
Performing system checks...

Unhandled exception in thread started by <function check_errors.<locals>.wrapper at 0x7f0bcef86378>
Traceback (most recent call last):
  File "/usr/local/lib/python3.4/dist-packages/django/db/backends/utils.py", line 64, in execute
    return self.cursor.execute(sql, params)
  File "/usr/local/lib/python3.4/dist-packages/django/db/backends/mysql/base.py", line 112, in execute
    return self.cursor.execute(query, args)
  File "/usr/local/lib/python3.4/dist-packages/MySQLdb/cursors.py", line 250, in execute
    self.errorhandler(self, exc, value)
  File "/usr/local/lib/python3.4/dist-packages/MySQLdb/connections.py", line 42, in defaulterrorhandler
    raise errorvalue
  File "/usr/local/lib/python3.4/dist-packages/MySQLdb/cursors.py", line 247, in execute
    res = self._query(query)
  File "/usr/local/lib/python3.4/dist-packages/MySQLdb/cursors.py", line 411, in _query
    rowcount = self._do_query(q)
  File "/usr/local/lib/python3.4/dist-packages/MySQLdb/cursors.py", line 374, in _do_query
    db.query(q)
  File "/usr/local/lib/python3.4/dist-packages/MySQLdb/connections.py", line 270, in query
    _mysql.connection.query(self, query)
_mysql_exceptions.ProgrammingError: (1146, "Table 'rc_builder_app_data.rcapp_targetslistgroup' doesn't exist")

The above exception was the direct cause of the following exception:

Traceback (most recent call last):
  File "/usr/local/lib/python3.4/dist-packages/django/utils/autoreload.py", line 226, in wrapper
    fn(*args, **kwargs)
  File "/usr/local/lib/python3.4/dist-packages/django/core/management/commands/runserver.py", line 121, in inner_run
    self.check(display_num_errors=True)
  File "/usr/local/lib/python3.4/dist-packages/django/core/management/base.py", line 385, in check
    include_deployment_checks=include_deployment_checks,
  File "/usr/local/lib/python3.4/dist-packages/django/core/management/base.py", line 372, in _run_checks
    return checks.run_checks(**kwargs)
  File "/usr/local/lib/python3.4/dist-packages/django/core/checks/registry.py", line 81, in run_checks
    new_errors = check(app_configs=app_configs)
  File "/usr/local/lib/python3.4/dist-packages/django/core/checks/urls.py", line 14, in check_url_config
    return check_resolver(resolver)
  File "/usr/local/lib/python3.4/dist-packages/django/core/checks/urls.py", line 24, in check_resolver
    for pattern in resolver.url_patterns:
  File "/usr/local/lib/python3.4/dist-packages/django/utils/functional.py", line 35, in __get__
    res = instance.__dict__[self.name] = self.func(instance)
  File "/usr/local/lib/python3.4/dist-packages/django/urls/resolvers.py", line 310, in url_patterns
    patterns = getattr(self.urlconf_module, "urlpatterns", self.urlconf_module)
  File "/usr/local/lib/python3.4/dist-packages/django/utils/functional.py", line 35, in __get__
    res = instance.__dict__[self.name] = self.func(instance)
  File "/usr/local/lib/python3.4/dist-packages/django/urls/resolvers.py", line 303, in urlconf_module
    return import_module(self.urlconf_name)
  File "/usr/lib/python3.4/importlib/__init__.py", line 109, in import_module
    return _bootstrap._gcd_import(name[level:], package, level)
  File "<frozen importlib._bootstrap>", line 2254, in _gcd_import
  File "<frozen importlib._bootstrap>", line 2237, in _find_and_load
  File "<frozen importlib._bootstrap>", line 2226, in _find_and_load_unlocked
  File "<frozen importlib._bootstrap>", line 1200, in _load_unlocked
  File "<frozen importlib._bootstrap>", line 1129, in _exec
  File "<frozen importlib._bootstrap>", line 1471, in exec_module
  File "<frozen importlib._bootstrap>", line 321, in _call_with_frames_removed
  File "/etc/side_projects/RCBuilder/RCBuilder/urls.py", line 25, in <module>
    url(r'^portal/', include('rcapp.urls')),
  File "/usr/local/lib/python3.4/dist-packages/django/conf/urls/__init__.py", line 50, in include
    urlconf_module = import_module(urlconf_module)
  File "/usr/lib/python3.4/importlib/__init__.py", line 109, in import_module
    return _bootstrap._gcd_import(name[level:], package, level)
  File "<frozen importlib._bootstrap>", line 2254, in _gcd_import
  File "<frozen importlib._bootstrap>", line 2237, in _find_and_load
  File "<frozen importlib._bootstrap>", line 2226, in _find_and_load_unlocked
  File "<frozen importlib._bootstrap>", line 1200, in _load_unlocked
  File "<frozen importlib._bootstrap>", line 1129, in _exec
  File "<frozen importlib._bootstrap>", line 1471, in exec_module
  File "<frozen importlib._bootstrap>", line 321, in _call_with_frames_removed
  File "/etc/side_projects/RCBuilder/rcapp/urls.py", line 3, in <module>
    from . import views
  File "/etc/side_projects/RCBuilder/rcapp/views.py", line 10, in <module>
    from .forms import RCForm, TargetForm, ResourceForm, ActivityForm, OutputForm, OutcomeForm, ImpactForm, OutputIndicatorForm, OutputPlanFactForm, OutputMethodForm, OutcomeIndicatorForm, OutcomePlanFactForm, OutcomeMethodForm, ImpactIndicatorForm, ImpactPlanFactForm
  File "/etc/side_projects/RCBuilder/rcapp/forms.py", line 44, in <module>
    class TargetForm(forms.ModelForm):
  File "/etc/side_projects/RCBuilder/rcapp/forms.py", line 45, in TargetForm
    class Meta:
  File "/etc/side_projects/RCBuilder/rcapp/forms.py", line 50, in Meta
    for group in groups:
  File "/usr/local/lib/python3.4/dist-packages/django/db/models/query.py", line 256, in __iter__
    self._fetch_all()
  File "/usr/local/lib/python3.4/dist-packages/django/db/models/query.py", line 1085, in _fetch_all
    self._result_cache = list(self.iterator())
  File "/usr/local/lib/python3.4/dist-packages/django/db/models/query.py", line 54, in __iter__
    results = compiler.execute_sql()
  File "/usr/local/lib/python3.4/dist-packages/django/db/models/sql/compiler.py", line 835, in execute_sql
    cursor.execute(sql, params)
  File "/usr/local/lib/python3.4/dist-packages/django/db/backends/utils.py", line 79, in execute
    return super(CursorDebugWrapper, self).execute(sql, params)
  File "/usr/local/lib/python3.4/dist-packages/django/db/backends/utils.py", line 64, in execute
    return self.cursor.execute(sql, params)
  File "/usr/local/lib/python3.4/dist-packages/django/db/utils.py", line 94, in __exit__
    six.reraise(dj_exc_type, dj_exc_value, traceback)
  File "/usr/local/lib/python3.4/dist-packages/django/utils/six.py", line 685, in reraise
    raise value.with_traceback(tb)
  File "/usr/local/lib/python3.4/dist-packages/django/db/backends/utils.py", line 64, in execute
    return self.cursor.execute(sql, params)
  File "/usr/local/lib/python3.4/dist-packages/django/db/backends/mysql/base.py", line 112, in execute
    return self.cursor.execute(query, args)
  File "/usr/local/lib/python3.4/dist-packages/MySQLdb/cursors.py", line 250, in execute
    self.errorhandler(self, exc, value)
  File "/usr/local/lib/python3.4/dist-packages/MySQLdb/connections.py", line 42, in defaulterrorhandler
    raise errorvalue
  File "/usr/local/lib/python3.4/dist-packages/MySQLdb/cursors.py", line 247, in execute
    res = self._query(query)
  File "/usr/local/lib/python3.4/dist-packages/MySQLdb/cursors.py", line 411, in _query
    rowcount = self._do_query(q)
  File "/usr/local/lib/python3.4/dist-packages/MySQLdb/cursors.py", line 374, in _do_query
    db.query(q)
  File "/usr/local/lib/python3.4/dist-packages/MySQLdb/connections.py", line 270, in query
    _mysql.connection.query(self, query)
django.db.utils.ProgrammingError: (1146, "Table 'rc_builder_app_data.rcapp_targetslistgroup' doesn't exist")
Performing system checks...

Unhandled exception in thread started by <function check_errors.<locals>.wrapper at 0x7fa72c9da378>
Traceback (most recent call last):
  File "/usr/local/lib/python3.4/dist-packages/django/db/backends/utils.py", line 64, in execute
    return self.cursor.execute(sql, params)
  File "/usr/local/lib/python3.4/dist-packages/django/db/backends/mysql/base.py", line 112, in execute
    return self.cursor.execute(query, args)
  File "/usr/local/lib/python3.4/dist-packages/MySQLdb/cursors.py", line 250, in execute
    self.errorhandler(self, exc, value)
  File "/usr/local/lib/python3.4/dist-packages/MySQLdb/connections.py", line 42, in defaulterrorhandler
    raise errorvalue
  File "/usr/local/lib/python3.4/dist-packages/MySQLdb/cursors.py", line 247, in execute
    res = self._query(query)
  File "/usr/local/lib/python3.4/dist-packages/MySQLdb/cursors.py", line 411, in _query
    rowcount = self._do_query(q)
  File "/usr/local/lib/python3.4/dist-packages/MySQLdb/cursors.py", line 374, in _do_query
    db.query(q)
  File "/usr/local/lib/python3.4/dist-packages/MySQLdb/connections.py", line 270, in query
    _mysql.connection.query(self, query)
_mysql_exceptions.ProgrammingError: (1146, "Table 'rc_builder_app_data.rcapp_targetslistgroup' doesn't exist")

The above exception was the direct cause of the following exception:

Traceback (most recent call last):
  File "/usr/local/lib/python3.4/dist-packages/django/utils/autoreload.py", line 226, in wrapper
    fn(*args, **kwargs)
  File "/usr/local/lib/python3.4/dist-packages/django/core/management/commands/runserver.py", line 121, in inner_run
    self.check(display_num_errors=True)
  File "/usr/local/lib/python3.4/dist-packages/django/core/management/base.py", line 385, in check
    include_deployment_checks=include_deployment_checks,
  File "/usr/local/lib/python3.4/dist-packages/django/core/management/base.py", line 372, in _run_checks
    return checks.run_checks(**kwargs)
  File "/usr/local/lib/python3.4/dist-packages/django/core/checks/registry.py", line 81, in run_checks
    new_errors = check(app_configs=app_configs)
  File "/usr/local/lib/python3.4/dist-packages/django/core/checks/urls.py", line 14, in check_url_config
    return check_resolver(resolver)
  File "/usr/local/lib/python3.4/dist-packages/django/core/checks/urls.py", line 24, in check_resolver
    for pattern in resolver.url_patterns:
  File "/usr/local/lib/python3.4/dist-packages/django/utils/functional.py", line 35, in __get__
    res = instance.__dict__[self.name] = self.func(instance)
  File "/usr/local/lib/python3.4/dist-packages/django/urls/resolvers.py", line 310, in url_patterns
    patterns = getattr(self.urlconf_module, "urlpatterns", self.urlconf_module)
  File "/usr/local/lib/python3.4/dist-packages/django/utils/functional.py", line 35, in __get__
    res = instance.__dict__[self.name] = self.func(instance)
  File "/usr/local/lib/python3.4/dist-packages/django/urls/resolvers.py", line 303, in urlconf_module
    return import_module(self.urlconf_name)
  File "/usr/lib/python3.4/importlib/__init__.py", line 109, in import_module
    return _bootstrap._gcd_import(name[level:], package, level)
  File "<frozen importlib._bootstrap>", line 2254, in _gcd_import
  File "<frozen importlib._bootstrap>", line 2237, in _find_and_load
  File "<frozen importlib._bootstrap>", line 2226, in _find_and_load_unlocked
  File "<frozen importlib._bootstrap>", line 1200, in _load_unlocked
  File "<frozen importlib._bootstrap>", line 1129, in _exec
  File "<frozen importlib._bootstrap>", line 1471, in exec_module
  File "<frozen importlib._bootstrap>", line 321, in _call_with_frames_removed
  File "/etc/side_projects/RCBuilder/RCBuilder/urls.py", line 25, in <module>
    url(r'^portal/', include('rcapp.urls')),
  File "/usr/local/lib/python3.4/dist-packages/django/conf/urls/__init__.py", line 50, in include
    urlconf_module = import_module(urlconf_module)
  File "/usr/lib/python3.4/importlib/__init__.py", line 109, in import_module
    return _bootstrap._gcd_import(name[level:], package, level)
  File "<frozen importlib._bootstrap>", line 2254, in _gcd_import
  File "<frozen importlib._bootstrap>", line 2237, in _find_and_load
  File "<frozen importlib._bootstrap>", line 2226, in _find_and_load_unlocked
  File "<frozen importlib._bootstrap>", line 1200, in _load_unlocked
  File "<frozen importlib._bootstrap>", line 1129, in _exec
  File "<frozen importlib._bootstrap>", line 1471, in exec_module
  File "<frozen importlib._bootstrap>", line 321, in _call_with_frames_removed
  File "/etc/side_projects/RCBuilder/rcapp/urls.py", line 3, in <module>
    from . import views
  File "/etc/side_projects/RCBuilder/rcapp/views.py", line 10, in <module>
    from .forms import RCForm, TargetForm, ResourceForm, ActivityForm, OutputForm, OutcomeForm, ImpactForm, OutputIndicatorForm, OutputPlanFactForm, OutputMethodForm, OutcomeIndicatorForm, OutcomePlanFactForm, OutcomeMethodForm, ImpactIndicatorForm, ImpactPlanFactForm
  File "/etc/side_projects/RCBuilder/rcapp/forms.py", line 44, in <module>
    class TargetForm(forms.ModelForm):
  File "/etc/side_projects/RCBuilder/rcapp/forms.py", line 45, in TargetForm
    class Meta:
  File "/etc/side_projects/RCBuilder/rcapp/forms.py", line 50, in Meta
    for group in groups:
  File "/usr/local/lib/python3.4/dist-packages/django/db/models/query.py", line 256, in __iter__
    self._fetch_all()
  File "/usr/local/lib/python3.4/dist-packages/django/db/models/query.py", line 1085, in _fetch_all
    self._result_cache = list(self.iterator())
  File "/usr/local/lib/python3.4/dist-packages/django/db/models/query.py", line 54, in __iter__
    results = compiler.execute_sql()
  File "/usr/local/lib/python3.4/dist-packages/django/db/models/sql/compiler.py", line 835, in execute_sql
    cursor.execute(sql, params)
  File "/usr/local/lib/python3.4/dist-packages/django/db/backends/utils.py", line 79, in execute
    return super(CursorDebugWrapper, self).execute(sql, params)
  File "/usr/local/lib/python3.4/dist-packages/django/db/backends/utils.py", line 64, in execute
    return self.cursor.execute(sql, params)
  File "/usr/local/lib/python3.4/dist-packages/django/db/utils.py", line 94, in __exit__
    six.reraise(dj_exc_type, dj_exc_value, traceback)
  File "/usr/local/lib/python3.4/dist-packages/django/utils/six.py", line 685, in reraise
    raise value.with_traceback(tb)
  File "/usr/local/lib/python3.4/dist-packages/django/db/backends/utils.py", line 64, in execute
    return self.cursor.execute(sql, params)
  File "/usr/local/lib/python3.4/dist-packages/django/db/backends/mysql/base.py", line 112, in execute
    return self.cursor.execute(query, args)
  File "/usr/local/lib/python3.4/dist-packages/MySQLdb/cursors.py", line 250, in execute
    self.errorhandler(self, exc, value)
  File "/usr/local/lib/python3.4/dist-packages/MySQLdb/connections.py", line 42, in defaulterrorhandler
    raise errorvalue
  File "/usr/local/lib/python3.4/dist-packages/MySQLdb/cursors.py", line 247, in execute
    res = self._query(query)
  File "/usr/local/lib/python3.4/dist-packages/MySQLdb/cursors.py", line 411, in _query
    rowcount = self._do_query(q)
  File "/usr/local/lib/python3.4/dist-packages/MySQLdb/cursors.py", line 374, in _do_query
    db.query(q)
  File "/usr/local/lib/python3.4/dist-packages/MySQLdb/connections.py", line 270, in query
    _mysql.connection.query(self, query)
django.db.utils.ProgrammingError: (1146, "Table 'rc_builder_app_data.rcapp_targetslistgroup' doesn't exist")
Performing system checks...

Performing system checks...

System check identified no issues (0 silenced).
December 14, 2016 - 01:17:06
Django version 1.10, using settings 'RCBuilder.settings'
Starting development server at http://0.0.0.0:8080/
Quit the server with CONTROL-C.
Performing system checks...

System check identified no issues (0 silenced).
December 14, 2016 - 01:17:11
Django version 1.10, using settings 'RCBuilder.settings'
Starting development server at http://0.0.0.0:8080/
Quit the server with CONTROL-C.
Unhandled exception in thread started by <function check_errors.<locals>.wrapper at 0x7f190fa34048>
Traceback (most recent call last):
  File "/usr/local/lib/python3.4/dist-packages/django/utils/autoreload.py", line 226, in wrapper
    fn(*args, **kwargs)
  File "/usr/local/lib/python3.4/dist-packages/django/core/management/commands/runserver.py", line 121, in inner_run
    self.check(display_num_errors=True)
  File "/usr/local/lib/python3.4/dist-packages/django/core/management/base.py", line 385, in check
    include_deployment_checks=include_deployment_checks,
  File "/usr/local/lib/python3.4/dist-packages/django/core/management/base.py", line 372, in _run_checks
    return checks.run_checks(**kwargs)
  File "/usr/local/lib/python3.4/dist-packages/django/core/checks/registry.py", line 81, in run_checks
    new_errors = check(app_configs=app_configs)
  File "/usr/local/lib/python3.4/dist-packages/django/core/checks/urls.py", line 14, in check_url_config
    return check_resolver(resolver)
  File "/usr/local/lib/python3.4/dist-packages/django/core/checks/urls.py", line 24, in check_resolver
    for pattern in resolver.url_patterns:
  File "/usr/local/lib/python3.4/dist-packages/django/utils/functional.py", line 35, in __get__
    res = instance.__dict__[self.name] = self.func(instance)
  File "/usr/local/lib/python3.4/dist-packages/django/urls/resolvers.py", line 310, in url_patterns
    patterns = getattr(self.urlconf_module, "urlpatterns", self.urlconf_module)
  File "/usr/local/lib/python3.4/dist-packages/django/utils/functional.py", line 35, in __get__
    res = instance.__dict__[self.name] = self.func(instance)
  File "/usr/local/lib/python3.4/dist-packages/django/urls/resolvers.py", line 303, in urlconf_module
    return import_module(self.urlconf_name)
  File "/usr/lib/python3.4/importlib/__init__.py", line 109, in import_module
    return _bootstrap._gcd_import(name[level:], package, level)
  File "<frozen importlib._bootstrap>", line 2254, in _gcd_import
  File "<frozen importlib._bootstrap>", line 2237, in _find_and_load
  File "<frozen importlib._bootstrap>", line 2226, in _find_and_load_unlocked
  File "<frozen importlib._bootstrap>", line 1200, in _load_unlocked
  File "<frozen importlib._bootstrap>", line 1129, in _exec
  File "<frozen importlib._bootstrap>", line 1471, in exec_module
  File "<frozen importlib._bootstrap>", line 321, in _call_with_frames_removed
  File "/etc/side_projects/RCBuilder/RCBuilder/urls.py", line 25, in <module>
    url(r'^portal/', include('rcapp.urls')),
  File "/usr/local/lib/python3.4/dist-packages/django/conf/urls/__init__.py", line 50, in include
    urlconf_module = import_module(urlconf_module)
  File "/usr/lib/python3.4/importlib/__init__.py", line 109, in import_module
    return _bootstrap._gcd_import(name[level:], package, level)
  File "<frozen importlib._bootstrap>", line 2254, in _gcd_import
  File "<frozen importlib._bootstrap>", line 2237, in _find_and_load
  File "<frozen importlib._bootstrap>", line 2226, in _find_and_load_unlocked
  File "<frozen importlib._bootstrap>", line 1200, in _load_unlocked
  File "<frozen importlib._bootstrap>", line 1129, in _exec
  File "<frozen importlib._bootstrap>", line 1471, in exec_module
  File "<frozen importlib._bootstrap>", line 321, in _call_with_frames_removed
  File "/etc/side_projects/RCBuilder/rcapp/urls.py", line 3, in <module>
    from . import views
  File "/etc/side_projects/RCBuilder/rcapp/views.py", line 10, in <module>
    from .forms import RCForm, TargetForm, ResourceForm, ActivityForm, OutputForm, OutcomeForm, ImpactForm, OutputIndicatorForm, OutputPlanFactForm, OutputMethodForm, OutcomeIndicatorForm, OutcomePlanFactForm, OutcomeMethodForm, ImpactIndicatorForm, ImpactPlanFactForm
  File "/etc/side_projects/RCBuilder/rcapp/forms.py", line 44, in <module>
    class TargetForm(forms.ModelForm):
  File "/etc/side_projects/RCBuilder/rcapp/forms.py", line 45, in TargetForm
    class Meta:
  File "/etc/side_projects/RCBuilder/rcapp/forms.py", line 55, in Meta
    choises = choises + [((item.value, item.value),) for item in TargetsListItem.object if item.item_of not in groups]
AttributeError: type object 'TargetsListItem' has no attribute 'object'
Performing system checks...

Unhandled exception in thread started by <function check_errors.<locals>.wrapper at 0x7f0004ad5378>
Traceback (most recent call last):
  File "/usr/local/lib/python3.4/dist-packages/django/utils/autoreload.py", line 226, in wrapper
    fn(*args, **kwargs)
  File "/usr/local/lib/python3.4/dist-packages/django/core/management/commands/runserver.py", line 121, in inner_run
    self.check(display_num_errors=True)
  File "/usr/local/lib/python3.4/dist-packages/django/core/management/base.py", line 385, in check
    include_deployment_checks=include_deployment_checks,
  File "/usr/local/lib/python3.4/dist-packages/django/core/management/base.py", line 372, in _run_checks
    return checks.run_checks(**kwargs)
  File "/usr/local/lib/python3.4/dist-packages/django/core/checks/registry.py", line 81, in run_checks
    new_errors = check(app_configs=app_configs)
  File "/usr/local/lib/python3.4/dist-packages/django/core/checks/urls.py", line 14, in check_url_config
    return check_resolver(resolver)
  File "/usr/local/lib/python3.4/dist-packages/django/core/checks/urls.py", line 24, in check_resolver
    for pattern in resolver.url_patterns:
  File "/usr/local/lib/python3.4/dist-packages/django/utils/functional.py", line 35, in __get__
    res = instance.__dict__[self.name] = self.func(instance)
  File "/usr/local/lib/python3.4/dist-packages/django/urls/resolvers.py", line 310, in url_patterns
    patterns = getattr(self.urlconf_module, "urlpatterns", self.urlconf_module)
  File "/usr/local/lib/python3.4/dist-packages/django/utils/functional.py", line 35, in __get__
    res = instance.__dict__[self.name] = self.func(instance)
  File "/usr/local/lib/python3.4/dist-packages/django/urls/resolvers.py", line 303, in urlconf_module
    return import_module(self.urlconf_name)
  File "/usr/lib/python3.4/importlib/__init__.py", line 109, in import_module
    return _bootstrap._gcd_import(name[level:], package, level)
  File "<frozen importlib._bootstrap>", line 2254, in _gcd_import
  File "<frozen importlib._bootstrap>", line 2237, in _find_and_load
  File "<frozen importlib._bootstrap>", line 2226, in _find_and_load_unlocked
  File "<frozen importlib._bootstrap>", line 1200, in _load_unlocked
  File "<frozen importlib._bootstrap>", line 1129, in _exec
  File "<frozen importlib._bootstrap>", line 1471, in exec_module
  File "<frozen importlib._bootstrap>", line 321, in _call_with_frames_removed
  File "/etc/side_projects/RCBuilder/RCBuilder/urls.py", line 25, in <module>
    url(r'^portal/', include('rcapp.urls')),
  File "/usr/local/lib/python3.4/dist-packages/django/conf/urls/__init__.py", line 50, in include
    urlconf_module = import_module(urlconf_module)
  File "/usr/lib/python3.4/importlib/__init__.py", line 109, in import_module
    return _bootstrap._gcd_import(name[level:], package, level)
  File "<frozen importlib._bootstrap>", line 2254, in _gcd_import
  File "<frozen importlib._bootstrap>", line 2237, in _find_and_load
  File "<frozen importlib._bootstrap>", line 2226, in _find_and_load_unlocked
  File "<frozen importlib._bootstrap>", line 1200, in _load_unlocked
  File "<frozen importlib._bootstrap>", line 1129, in _exec
  File "<frozen importlib._bootstrap>", line 1471, in exec_module
  File "<frozen importlib._bootstrap>", line 321, in _call_with_frames_removed
  File "/etc/side_projects/RCBuilder/rcapp/urls.py", line 3, in <module>
    from . import views
  File "/etc/side_projects/RCBuilder/rcapp/views.py", line 10, in <module>
    from .forms import RCForm, TargetForm, ResourceForm, ActivityForm, OutputForm, OutcomeForm, ImpactForm, OutputIndicatorForm, OutputPlanFactForm, OutputMethodForm, OutcomeIndicatorForm, OutcomePlanFactForm, OutcomeMethodForm, ImpactIndicatorForm, ImpactPlanFactForm
  File "/etc/side_projects/RCBuilder/rcapp/forms.py", line 44, in <module>
    class TargetForm(forms.ModelForm):
  File "/etc/side_projects/RCBuilder/rcapp/forms.py", line 45, in TargetForm
    class Meta:
  File "/etc/side_projects/RCBuilder/rcapp/forms.py", line 55, in Meta
    choises = choises + [((item.value, item.value),) for item in TargetsListItem.object if item.item_of not in groups]
AttributeError: type object 'TargetsListItem' has no attribute 'object'
Performing system checks...

Unhandled exception in thread started by <function check_errors.<locals>.wrapper at 0x7f170984e048>
Traceback (most recent call last):
  File "/usr/local/lib/python3.4/dist-packages/django/utils/autoreload.py", line 226, in wrapper
    fn(*args, **kwargs)
  File "/usr/local/lib/python3.4/dist-packages/django/core/management/commands/runserver.py", line 121, in inner_run
    self.check(display_num_errors=True)
  File "/usr/local/lib/python3.4/dist-packages/django/core/management/base.py", line 385, in check
    include_deployment_checks=include_deployment_checks,
  File "/usr/local/lib/python3.4/dist-packages/django/core/management/base.py", line 372, in _run_checks
    return checks.run_checks(**kwargs)
  File "/usr/local/lib/python3.4/dist-packages/django/core/checks/registry.py", line 81, in run_checks
    new_errors = check(app_configs=app_configs)
  File "/usr/local/lib/python3.4/dist-packages/django/core/checks/urls.py", line 14, in check_url_config
    return check_resolver(resolver)
  File "/usr/local/lib/python3.4/dist-packages/django/core/checks/urls.py", line 24, in check_resolver
    for pattern in resolver.url_patterns:
  File "/usr/local/lib/python3.4/dist-packages/django/utils/functional.py", line 35, in __get__
    res = instance.__dict__[self.name] = self.func(instance)
  File "/usr/local/lib/python3.4/dist-packages/django/urls/resolvers.py", line 310, in url_patterns
    patterns = getattr(self.urlconf_module, "urlpatterns", self.urlconf_module)
  File "/usr/local/lib/python3.4/dist-packages/django/utils/functional.py", line 35, in __get__
    res = instance.__dict__[self.name] = self.func(instance)
  File "/usr/local/lib/python3.4/dist-packages/django/urls/resolvers.py", line 303, in urlconf_module
    return import_module(self.urlconf_name)
  File "/usr/lib/python3.4/importlib/__init__.py", line 109, in import_module
    return _bootstrap._gcd_import(name[level:], package, level)
  File "<frozen importlib._bootstrap>", line 2254, in _gcd_import
  File "<frozen importlib._bootstrap>", line 2237, in _find_and_load
  File "<frozen importlib._bootstrap>", line 2226, in _find_and_load_unlocked
  File "<frozen importlib._bootstrap>", line 1200, in _load_unlocked
  File "<frozen importlib._bootstrap>", line 1129, in _exec
  File "<frozen importlib._bootstrap>", line 1471, in exec_module
  File "<frozen importlib._bootstrap>", line 321, in _call_with_frames_removed
  File "/etc/side_projects/RCBuilder/RCBuilder/urls.py", line 25, in <module>
    url(r'^portal/', include('rcapp.urls')),
  File "/usr/local/lib/python3.4/dist-packages/django/conf/urls/__init__.py", line 50, in include
    urlconf_module = import_module(urlconf_module)
  File "/usr/lib/python3.4/importlib/__init__.py", line 109, in import_module
    return _bootstrap._gcd_import(name[level:], package, level)
  File "<frozen importlib._bootstrap>", line 2254, in _gcd_import
  File "<frozen importlib._bootstrap>", line 2237, in _find_and_load
  File "<frozen importlib._bootstrap>", line 2226, in _find_and_load_unlocked
  File "<frozen importlib._bootstrap>", line 1200, in _load_unlocked
  File "<frozen importlib._bootstrap>", line 1129, in _exec
  File "<frozen importlib._bootstrap>", line 1471, in exec_module
  File "<frozen importlib._bootstrap>", line 321, in _call_with_frames_removed
  File "/etc/side_projects/RCBuilder/rcapp/urls.py", line 3, in <module>
    from . import views
  File "/etc/side_projects/RCBuilder/rcapp/views.py", line 10, in <module>
    from .forms import RCForm, TargetForm, ResourceForm, ActivityForm, OutputForm, OutcomeForm, ImpactForm, OutputIndicatorForm, OutputPlanFactForm, OutputMethodForm, OutcomeIndicatorForm, OutcomePlanFactForm, OutcomeMethodForm, ImpactIndicatorForm, ImpactPlanFactForm
  File "/etc/side_projects/RCBuilder/rcapp/forms.py", line 44, in <module>
    class TargetForm(forms.ModelForm):
  File "/etc/side_projects/RCBuilder/rcapp/forms.py", line 45, in TargetForm
    class Meta:
  File "/etc/side_projects/RCBuilder/rcapp/forms.py", line 55, in Meta
    choises = choises + tuple([((item.value, item.value),) for item in TargetsListItem.object if item.item_of not in groups])
AttributeError: type object 'TargetsListItem' has no attribute 'object'
Performing system checks...

Unhandled exception in thread started by <function check_errors.<locals>.wrapper at 0x7f1b8f584378>
Traceback (most recent call last):
  File "/usr/local/lib/python3.4/dist-packages/django/utils/autoreload.py", line 226, in wrapper
    fn(*args, **kwargs)
  File "/usr/local/lib/python3.4/dist-packages/django/core/management/commands/runserver.py", line 121, in inner_run
    self.check(display_num_errors=True)
  File "/usr/local/lib/python3.4/dist-packages/django/core/management/base.py", line 385, in check
    include_deployment_checks=include_deployment_checks,
  File "/usr/local/lib/python3.4/dist-packages/django/core/management/base.py", line 372, in _run_checks
    return checks.run_checks(**kwargs)
  File "/usr/local/lib/python3.4/dist-packages/django/core/checks/registry.py", line 81, in run_checks
    new_errors = check(app_configs=app_configs)
  File "/usr/local/lib/python3.4/dist-packages/django/core/checks/urls.py", line 14, in check_url_config
    return check_resolver(resolver)
  File "/usr/local/lib/python3.4/dist-packages/django/core/checks/urls.py", line 24, in check_resolver
    for pattern in resolver.url_patterns:
  File "/usr/local/lib/python3.4/dist-packages/django/utils/functional.py", line 35, in __get__
    res = instance.__dict__[self.name] = self.func(instance)
  File "/usr/local/lib/python3.4/dist-packages/django/urls/resolvers.py", line 310, in url_patterns
    patterns = getattr(self.urlconf_module, "urlpatterns", self.urlconf_module)
  File "/usr/local/lib/python3.4/dist-packages/django/utils/functional.py", line 35, in __get__
    res = instance.__dict__[self.name] = self.func(instance)
  File "/usr/local/lib/python3.4/dist-packages/django/urls/resolvers.py", line 303, in urlconf_module
    return import_module(self.urlconf_name)
  File "/usr/lib/python3.4/importlib/__init__.py", line 109, in import_module
    return _bootstrap._gcd_import(name[level:], package, level)
  File "<frozen importlib._bootstrap>", line 2254, in _gcd_import
  File "<frozen importlib._bootstrap>", line 2237, in _find_and_load
  File "<frozen importlib._bootstrap>", line 2226, in _find_and_load_unlocked
  File "<frozen importlib._bootstrap>", line 1200, in _load_unlocked
  File "<frozen importlib._bootstrap>", line 1129, in _exec
  File "<frozen importlib._bootstrap>", line 1471, in exec_module
  File "<frozen importlib._bootstrap>", line 321, in _call_with_frames_removed
  File "/etc/side_projects/RCBuilder/RCBuilder/urls.py", line 25, in <module>
    url(r'^portal/', include('rcapp.urls')),
  File "/usr/local/lib/python3.4/dist-packages/django/conf/urls/__init__.py", line 50, in include
    urlconf_module = import_module(urlconf_module)
  File "/usr/lib/python3.4/importlib/__init__.py", line 109, in import_module
    return _bootstrap._gcd_import(name[level:], package, level)
  File "<frozen importlib._bootstrap>", line 2254, in _gcd_import
  File "<frozen importlib._bootstrap>", line 2237, in _find_and_load
  File "<frozen importlib._bootstrap>", line 2226, in _find_and_load_unlocked
  File "<frozen importlib._bootstrap>", line 1200, in _load_unlocked
  File "<frozen importlib._bootstrap>", line 1129, in _exec
  File "<frozen importlib._bootstrap>", line 1471, in exec_module
  File "<frozen importlib._bootstrap>", line 321, in _call_with_frames_removed
  File "/etc/side_projects/RCBuilder/rcapp/urls.py", line 3, in <module>
    from . import views
  File "/etc/side_projects/RCBuilder/rcapp/views.py", line 10, in <module>
    from .forms import RCForm, TargetForm, ResourceForm, ActivityForm, OutputForm, OutcomeForm, ImpactForm, OutputIndicatorForm, OutputPlanFactForm, OutputMethodForm, OutcomeIndicatorForm, OutcomePlanFactForm, OutcomeMethodForm, ImpactIndicatorForm, ImpactPlanFactForm
  File "/etc/side_projects/RCBuilder/rcapp/forms.py", line 44, in <module>
    class TargetForm(forms.ModelForm):
  File "/etc/side_projects/RCBuilder/rcapp/forms.py", line 45, in TargetForm
    class Meta:
  File "/etc/side_projects/RCBuilder/rcapp/forms.py", line 55, in Meta
    choises = choises + tuple([((item.value, item.value),) for item in TargetsListItem.object if item.item_of not in groups])
AttributeError: type object 'TargetsListItem' has no attribute 'object'
Performing system checks...

