Internal Server Error: /
Traceback (most recent call last):
  File "/usr/local/lib/python3.4/dist-packages/django/core/handlers/exception.py", line 39, in inner
    response = get_response(request)
  File "/usr/local/lib/python3.4/dist-packages/django/core/handlers/base.py", line 187, in _get_response
    response = self.process_exception_by_middleware(e, request)
  File "/usr/local/lib/python3.4/dist-packages/django/core/handlers/base.py", line 185, in _get_response
    response = wrapped_callback(request, *callback_args, **callback_kwargs)
  File "/etc/side_projects/RCBuilder/RCBuilder/views.py", line 8, in index
    return render(request, 'templates/main/index.html', {})
  File "/usr/local/lib/python3.4/dist-packages/django/shortcuts.py", line 30, in render
    content = loader.render_to_string(template_name, context, request, using=using)
  File "/usr/local/lib/python3.4/dist-packages/django/template/loader.py", line 67, in render_to_string
    template = get_template(template_name, using=using)
  File "/usr/local/lib/python3.4/dist-packages/django/template/loader.py", line 25, in get_template
    raise TemplateDoesNotExist(template_name, chain=chain)
django.template.exceptions.TemplateDoesNotExist: templates/main/index.html
[17/Nov/2016 17:12:18] "GET / HTTP/1.1" 500 75909
