[18/Nov/2016 15:59:17] "GET /admin/ HTTP/1.1" 200 2779
[18/Nov/2016 15:59:19] "GET /admin/ HTTP/1.1" 200 2779
[18/Nov/2016 15:59:19] "GET /static/admin/css/dashboard.css HTTP/1.1" 304 0
[18/Nov/2016 15:59:19] "GET /static/admin/css/base.css HTTP/1.1" 304 0
[18/Nov/2016 15:59:19] "GET /static/admin/css/fonts.css HTTP/1.1" 304 0
[18/Nov/2016 15:59:19] "GET /static/admin/fonts/Roboto-Light-webfont.woff HTTP/1.1" 304 0
[18/Nov/2016 15:59:19] "GET /static/admin/fonts/Roboto-Regular-webfont.woff HTTP/1.1" 304 0
[18/Nov/2016 15:59:19] "GET /static/admin/fonts/Roboto-Bold-webfont.woff HTTP/1.1" 304 0
Performing system checks...

System check identified no issues (0 silenced).
November 18, 2016 - 15:59:12
Django version 1.10, using settings 'RCBuilder.settings'
Starting development server at http://0.0.0.0:8080/
Quit the server with CONTROL-C.
Unhandled exception in thread started by <function check_errors.<locals>.wrapper at 0x7ff90d10a1e0>
Traceback (most recent call last):
  File "/usr/local/lib/python3.4/dist-packages/django/utils/autoreload.py", line 226, in wrapper
    fn(*args, **kwargs)
  File "/usr/local/lib/python3.4/dist-packages/django/core/management/commands/runserver.py", line 113, in inner_run
    autoreload.raise_last_exception()
  File "/usr/local/lib/python3.4/dist-packages/django/utils/autoreload.py", line 249, in raise_last_exception
    six.reraise(*_exception)
  File "/usr/local/lib/python3.4/dist-packages/django/utils/six.py", line 685, in reraise
    raise value.with_traceback(tb)
  File "/usr/local/lib/python3.4/dist-packages/django/utils/autoreload.py", line 226, in wrapper
    fn(*args, **kwargs)
  File "/usr/local/lib/python3.4/dist-packages/django/__init__.py", line 27, in setup
    apps.populate(settings.INSTALLED_APPS)
  File "/usr/local/lib/python3.4/dist-packages/django/apps/registry.py", line 115, in populate
    app_config.ready()
  File "/usr/local/lib/python3.4/dist-packages/django/contrib/admin/apps.py", line 23, in ready
    self.module.autodiscover()
  File "/usr/local/lib/python3.4/dist-packages/django/contrib/admin/__init__.py", line 26, in autodiscover
    autodiscover_modules('admin', register_to=site)
  File "/usr/local/lib/python3.4/dist-packages/django/utils/module_loading.py", line 50, in autodiscover_modules
    import_module('%s.%s' % (app_config.name, module_to_search))
  File "/usr/lib/python3.4/importlib/__init__.py", line 109, in import_module
    return _bootstrap._gcd_import(name[level:], package, level)
  File "<frozen importlib._bootstrap>", line 2254, in _gcd_import
  File "<frozen importlib._bootstrap>", line 2237, in _find_and_load
  File "<frozen importlib._bootstrap>", line 2226, in _find_and_load_unlocked
  File "<frozen importlib._bootstrap>", line 1200, in _load_unlocked
  File "<frozen importlib._bootstrap>", line 1129, in _exec
  File "<frozen importlib._bootstrap>", line 1471, in exec_module
  File "<frozen importlib._bootstrap>", line 321, in _call_with_frames_removed
  File "/etc/side_projects/RCBuilder/rcb/admin.py", line 4, in <module>
    admin.site.register(Description)
NameError: name 'Description' is not defined
Performing system checks...

System check identified no issues (0 silenced).
November 18, 2016 - 16:02:37
Django version 1.10, using settings 'RCBuilder.settings'
Starting development server at http://0.0.0.0:8080/
Quit the server with CONTROL-C.
